Workbook

Sheet Raw Games
A1: Date | B1: Where | C1: Half | D1: aa | E1: Alizé | F1: Allyn | G1: Bo | H1: Candace | I1: Charlene | J1: Clelia | K1: David | L1: Debby | M1: Espy | N1: Jack | O1: Jake | P1: Jan | Q1: Jeff M | R1: Jeff P | S1: Jeremy | T1: Jordan | U1: Karenina | V1: Karen | W1: Kas | X1: Melissa | Y1: Nancy | Z1: Ray | AA1: Sally | AB1: Sandy | AC1: Sara | AD1: Scott | AE1: Simon | AF1: Susan | AG1: Terry | AH1: Zach | AJ1: Min | AK1: Max | AL1: Winner | AM1: Loser | AN1: Players
A2: <?> | B2: Preston | I2: 690 | K2: 765 | L2: 520 | Y2: 695 | AB2: 700 | AJ2: =MIN($D2:$AI2) -> 520 | AK2: =MAX($D2:$AI2) -> 765 | AL2: =HLOOKUP(AJ2,{$D2:$AI2;$D$1:$AI$1},2,false) -> Debby | AM2: =HLOOKUP(AK2,{$D2:$AI2;$D$1:$AI$1},2,false) -> David | AN2: =count(D2:AI2) -> 5
A3: <?> | B3: Preston | K3: 380 | Y3: 335 | AA3: 775 | AC3: 225 | AJ3: =MIN($D3:$AI3) -> 225 | AK3: =MAX($D3:$AI3) -> 775 | AL3: =HLOOKUP(AJ3,{$D3:$AI3;$D$1:$AI$1},2,false) -> Sara | AM3: =HLOOKUP(AK3,{$D3:$AI3;$D$1:$AI$1},2,false) -> Sally | AN3: =count(D3:AI3) -> 4
A4: <?> | B4: Preston | I4: 385 | K4: 510 | Q4: 300 | Y4: 365 | AJ4: =MIN($D4:$AI4) -> 300 | AK4: =MAX($D4:$AI4) -> 510 | AL4: =HLOOKUP(AJ4,{$D4:$AI4;$D$1:$AI$1},2,false) -> Jeff M | AM4: =HLOOKUP(AK4,{$D4:$AI4;$D$1:$AI$1},2,false) -> David | AN4: =count(D4:AI4) -> 4
A5: <?> | B5: Preston | I5: 495 | K5: 195 | L5: 795 | Y5: 450 | AJ5: =MIN($D5:$AI5) -> 195 | AK5: =MAX($D5:$AI5) -> 795 | AL5: =HLOOKUP(AJ5,{$D5:$AI5;$D$1:$AI$1},2,false) -> David | AM5: =HLOOKUP(AK5,{$D5:$AI5;$D$1:$AI$1},2,false) -> Debby | AN5: =count(D5:AI5) -> 4
A6: <?> | B6: Preston | K6: 65 | L6: 485 | Y6: 540 | AJ6: =MIN($D6:$AI6) -> 65 | AK6: =MAX($D6:$AI6) -> 540 | AL6: =HLOOKUP(AJ6,{$D6:$AI6;$D$1:$AI$1},2,false) -> David | AM6: =HLOOKUP(AK6,{$D6:$AI6;$D$1:$AI$1},2,false) -> Nancy | AN6: =count(D6:AI6) -> 3
A7: <?> | B7: <?> | C7: Yes | D7: 150 | L7: 130 | Y7: 175 | AJ7: =MIN($D7:$AI7) -> 130 | AK7: =MAX($D7:$AI7) -> 175 | AL7: =HLOOKUP(AJ7,{$D7:$AI7;$D$1:$AI$1},2,false) -> Debby | AM7: =HLOOKUP(AK7,{$D7:$AI7;$D$1:$AI$1},2,false) -> Nancy | AN7: =count(D7:AI7) -> 3
A8: <?> | B8: Preston | I8: 280 | K8: 535 | L8: 525 | Y8: 900 | AJ8: =MIN($D8:$AI8) -> 280 | AK8: =MAX($D8:$AI8) -> 900 | AL8: =HLOOKUP(AJ8,{$D8:$AI8;$D$1:$AI$1},2,false) -> Charlene | AM8: =HLOOKUP(AK8,{$D8:$AI8;$D$1:$AI$1},2,false) -> Nancy | AN8: =count(D8:AI8) -> 4
A9: <?> | B9: Preston | I9: 460 | K9: 225 | L9: 395 | Y9: 675 | AJ9: =MIN($D9:$AI9) -> 225 | AK9: =MAX($D9:$AI9) -> 675 | AL9: =HLOOKUP(AJ9,{$D9:$AI9;$D$1:$AI$1},2,false) -> David | AM9: =HLOOKUP(AK9,{$D9:$AI9;$D$1:$AI$1},2,false) -> Nancy | AN9: =count(D9:AI9) -> 4
A10: <?> | B10: Preston | I10: 190 | K10: 450 | Q10: 305 | Y10: 550 | AJ10: =MIN($D10:$AI10) -> 190 | AK10: =MAX($D10:$AI10) -> 550 | AL10: =HLOOKUP(AJ10,{$D10:$AI10;$D$1:$AI$1},2,false) -> Charlene | AM10: =HLOOKUP(AK10,{$D10:$AI10;$D$1:$AI$1},2,false) -> Nancy | AN10: =count(D10:AI10) -> 4
A11: <?> | B11: Preston | I11: 400 | L11: 235 | Y11: 260 | AA11: 240 | AJ11: =MIN($D11:$AI11) -> 235 | AK11: =MAX($D11:$AI11) -> 400 | AL11: =HLOOKUP(AJ11,{$D11:$AI11;$D$1:$AI$1},2,false) -> Debby | AM11: =HLOOKUP(AK11,{$D11:$AI11;$D$1:$AI$1},2,false) -> Charlene | AN11: =count(D11:AI11) -> 4
A12: <?> | B12: Preston | I12: 165 | K12: 400 | L12: 250 | Y12: 190 | AJ12: =MIN($D12:$AI12) -> 165 | AK12: =MAX($D12:$AI12) -> 400 | AL12: =HLOOKUP(AJ12,{$D12:$AI12;$D$1:$AI$1},2,false) -> Charlene | AM12: =HLOOKUP(AK12,{$D12:$AI12;$D$1:$AI$1},2,false) -> David | AN12: =count(D12:AI12) -> 4
A13: <?> | B13: Preston | I13: 445 | L13: 370 | Q13: 465 | Y13: 430 | AJ13: =MIN($D13:$AI13) -> 370 | AK13: =MAX($D13:$AI13) -> 465 | AL13: =HLOOKUP(AJ13,{$D13:$AI13;$D$1:$AI$1},2,false) -> Debby | AM13: =HLOOKUP(AK13,{$D13:$AI13;$D$1:$AI$1},2,false) -> Jeff M | AN13: =count(D13:AI13) -> 4
A14: <?> | B14: Preston | I14: 525 | K14: 330 | L14: 540 | Y14: 675 | AJ14: =MIN($D14:$AI14) -> 330 | AK14: =MAX($D14:$AI14) -> 675 | AL14: =HLOOKUP(AJ14,{$D14:$AI14;$D$1:$AI$1},2,false) -> David | AM14: =HLOOKUP(AK14,{$D14:$AI14;$D$1:$AI$1},2,false) -> Nancy | AN14: =count(D14:AI14) -> 4
A15: <?> | B15: Preston | I15: 405 | K15: 385 | L15: 630 | Y15: 410 | AA15: 380 | AJ15: =MIN($D15:$AI15) -> 380 | AK15: =MAX($D15:$AI15) -> 630 | AL15: =HLOOKUP(AJ15,{$D15:$AI15;$D$1:$AI$1},2,false) -> Sally | AM15: =HLOOKUP(AK15,{$D15:$AI15;$D$1:$AI$1},2,false) -> Debby | AN15: =count(D15:AI15) -> 5
A16: <?> | B16: Preston | I16: 250 | K16: 690 | Y16: 515 | AA16: 800 | AJ16: =MIN($D16:$AI16) -> 250 | AK16: =MAX($D16:$AI16) -> 800 | AL16: =HLOOKUP(AJ16,{$D16:$AI16;$D$1:$AI$1},2,false) -> Charlene | AM16: =HLOOKUP(AK16,{$D16:$AI16;$D$1:$AI$1},2,false) -> Sally | AN16: =count(D16:AI16) -> 4
A17: <?> | B17: Preston | C17: Yes | F17: 80 | I17: 220 | Y17: 145 | AA17: 345 | AJ17: =MIN($D17:$AI17) -> 80 | AK17: =MAX($D17:$AI17) -> 345 | AL17: =HLOOKUP(AJ17,{$D17:$AI17;$D$1:$AI$1},2,false) -> Allyn | AM17: =HLOOKUP(AK17,{$D17:$AI17;$D$1:$AI$1},2,false) -> Sally | AN17: =count(D17:AI17) -> 4
A18: <?> | B18: Preston | C18: Yes | I18: 95 | K18: 240 | Q18: 95 | Y18: 265 | AJ18: =MIN($D18:$AI18) -> 95 | AK18: =MAX($D18:$AI18) -> 265 | AL18: =HLOOKUP(AJ18,{$D18:$AI18;$D$1:$AI$1},2,false) -> Charlene | AM18: =HLOOKUP(AK18,{$D18:$AI18;$D$1:$AI$1},2,false) -> Nancy | AN18: =count(D18:AI18) -> 4
A19: <?> | B19: Preston | I19: 455 | K19: 630 | L19: 395 | Y19: 380 | AA19: 650 | AJ19: =MIN($D19:$AI19) -> 380 | AK19: =MAX($D19:$AI19) -> 650 | AL19: =HLOOKUP(AJ19,{$D19:$AI19;$D$1:$AI$1},2,false) -> Nancy | AM19: =HLOOKUP(AK19,{$D19:$AI19;$D$1:$AI$1},2,false) -> Sally | AN19: =count(D19:AI19) -> 5
A20: <?> | B20: Preston | I20: 430 | K20: 290 | Y20: 275 | AC20: 940 | AJ20: =MIN($D20:$AI20) -> 275 | AK20: =MAX($D20:$AI20) -> 940 | AL20: =HLOOKUP(AJ20,{$D20:$AI20;$D$1:$AI$1},2,false) -> Nancy | AM20: =HLOOKUP(AK20,{$D20:$AI20;$D$1:$AI$1},2,false) -> Sara | AN20: =count(D20:AI20) -> 4
A21: <?> | B21: Preston | C21: Yes | F21: 490 | I21: 200 | K21: 310 | Y21: 160 | AJ21: =MIN($D21:$AI21) -> 160 | AK21: =MAX($D21:$AI21) -> 490 | AL21: =HLOOKUP(AJ21,{$D21:$AI21;$D$1:$AI$1},2,false) -> Nancy | AM21: =HLOOKUP(AK21,{$D21:$AI21;$D$1:$AI$1},2,false) -> Allyn | AN21: =count(D21:AI21) -> 4
A22: <?> | B22: Preston | C22: Yes | K22: 465 | L22: 405 | Y22: 75 | AB22: 420 | AJ22: =MIN($D22:$AI22) -> 75 | AK22: =MAX($D22:$AI22) -> 465 | AL22: =HLOOKUP(AJ22,{$D22:$AI22;$D$1:$AI$1},2,false) -> Nancy | AM22: =HLOOKUP(AK22,{$D22:$AI22;$D$1:$AI$1},2,false) -> David | AN22: =count(D22:AI22) -> 4
A23: <?> | B23: Preston | I23: 260 | K23: 285 | L23: 570 | Y23: 695 | AB23: 780 | AJ23: =MIN($D23:$AI23) -> 260 | AK23: =MAX($D23:$AI23) -> 780 | AL23: =HLOOKUP(AJ23,{$D23:$AI23;$D$1:$AI$1},2,false) -> Charlene | AM23: =HLOOKUP(AK23,{$D23:$AI23;$D$1:$AI$1},2,false) -> Sandy | AN23: =count(D23:AI23) -> 5
A24: <?> | B24: Superior | C24: Yes | I24: 245 | U24: 180 | Y24: 325 | AB24: 185 | AJ24: =MIN($D24:$AI24) -> 180 | AK24: =MAX($D24:$AI24) -> 325 | AL24: =HLOOKUP(AJ24,{$D24:$AI24;$D$1:$AI$1},2,false) -> Karenina | AM24: =HLOOKUP(AK24,{$D24:$AI24;$D$1:$AI$1},2,false) -> Nancy | AN24: =count(D24:AI24) -> 4
A25: <?> | B25: Preston | I25: 440 | K25: 420 | L25: 625 | U25: 575 | Y25: 445 | AB25: 895 | AJ25: =MIN($D25:$AI25) -> 420 | AK25: =MAX($D25:$AI25) -> 895 | AL25: =HLOOKUP(AJ25,{$D25:$AI25;$D$1:$AI$1},2,false) -> David | AM25: =HLOOKUP(AK25,{$D25:$AI25;$D$1:$AI$1},2,false) -> Sandy | AN25: =count(D25:AI25) -> 6
A26: <?> | B26: Superior | I26: 575 | K26: 510 | Q26: 565 | AA26: 400 | AJ26: =MIN($D26:$AI26) -> 400 | AK26: =MAX($D26:$AI26) -> 575 | AL26: =HLOOKUP(AJ26,{$D26:$AI26;$D$1:$AI$1},2,false) -> Sally | AM26: =HLOOKUP(AK26,{$D26:$AI26;$D$1:$AI$1},2,false) -> Charlene | AN26: =count(D26:AI26) -> 4
A27: <?> | B27: Superior | I27: 95 | K27: 705 | Q27: 775 | Y27: 400 | AJ27: =MIN($D27:$AI27) -> 95 | AK27: =MAX($D27:$AI27) -> 775 | AL27: =HLOOKUP(AJ27,{$D27:$AI27;$D$1:$AI$1},2,false) -> Charlene | AM27: =HLOOKUP(AK27,{$D27:$AI27;$D$1:$AI$1},2,false) -> Jeff M | AN27: =count(D27:AI27) -> 4
A28: <?> | B28: Preston | C28: Yes | I28: 155 | K28: 100 | L28: 495 | Q28: 240 | Y28: 235 | AJ28: =MIN($D28:$AI28) -> 100 | AK28: =MAX($D28:$AI28) -> 495 | AL28: =HLOOKUP(AJ28,{$D28:$AI28;$D$1:$AI$1},2,false) -> David | AM28: =HLOOKUP(AK28,{$D28:$AI28;$D$1:$AI$1},2,false) -> Debby | AN28: =count(D28:AI28) -> 5
A29: <?> | B29: Preston | C29: Yes | I29: 235 | K29: 135 | L29: 375 | Y29: 145 | AA29: 120 | AJ29: =MIN($D29:$AI29) -> 120 | AK29: =MAX($D29:$AI29) -> 375 | AL29: =HLOOKUP(AJ29,{$D29:$AI29;$D$1:$AI$1},2,false) -> Sally | AM29: =HLOOKUP(AK29,{$D29:$AI29;$D$1:$AI$1},2,false) -> Debby | AN29: =count(D29:AI29) -> 5
A30: <?> | B30: Preston | L30: 155 | Q30: 655 | Y30: 245 | AJ30: =MIN($D30:$AI30) -> 155 | AK30: =MAX($D30:$AI30) -> 655 | AL30: =HLOOKUP(AJ30,{$D30:$AI30;$D$1:$AI$1},2,false) -> Debby | AM30: =HLOOKUP(AK30,{$D30:$AI30;$D$1:$AI$1},2,false) -> Jeff M | AN30: =count(D30:AI30) -> 3
A31: <?> | B31: Preston | C31: Yes | K31: 160 | L31: 335 | Y31: 145 | AJ31: =MIN($D31:$AI31) -> 145 | AK31: =MAX($D31:$AI31) -> 335 | AL31: =HLOOKUP(AJ31,{$D31:$AI31;$D$1:$AI$1},2,false) -> Nancy | AM31: =HLOOKUP(AK31,{$D31:$AI31;$D$1:$AI$1},2,false) -> Debby | AN31: =count(D31:AI31) -> 3
A32: <?> | B32: Superior | C32: Yes | I32: 75 | K32: 325 | U32: 60 | Y32: 640 | AE32: 100 | AJ32: =MIN($D32:$AI32) -> 60 | AK32: =MAX($D32:$AI32) -> 640 | AL32: =HLOOKUP(AJ32,{$D32:$AI32;$D$1:$AI$1},2,false) -> Karenina | AM32: =HLOOKUP(AK32,{$D32:$AI32;$D$1:$AI$1},2,false) -> Nancy | AN32: =count(D32:AI32) -> 5
A33: <?> | B33: Preston | I33: 125 | K33: 655 | L33: 720 | Y33: 390 | AJ33: =MIN($D33:$AI33) -> 125 | AK33: =MAX($D33:$AI33) -> 720 | AL33: =HLOOKUP(AJ33,{$D33:$AI33;$D$1:$AI$1},2,false) -> Charlene | AM33: =HLOOKUP(AK33,{$D33:$AI33;$D$1:$AI$1},2,false) -> Debby | AN33: =count(D33:AI33) -> 4
A34: <?> | B34: Superior | I34: 175 | K34: 625 | L34: 285 | Y34: 185 | AJ34: =MIN($D34:$AI34) -> 175 | AK34: =MAX($D34:$AI34) -> 625 | AL34: =HLOOKUP(AJ34,{$D34:$AI34;$D$1:$AI$1},2,false) -> Charlene | AM34: =HLOOKUP(AK34,{$D34:$AI34;$D$1:$AI$1},2,false) -> David | AN34: =count(D34:AI34) -> 4
A35: <?> | B35: Preston | I35: 595 | K35: 455 | L35: 585 | Y35: 520 | AJ35: =MIN($D35:$AI35) -> 455 | AK35: =MAX($D35:$AI35) -> 595 | AL35: =HLOOKUP(AJ35,{$D35:$AI35;$D$1:$AI$1},2,false) -> David | AM35: =HLOOKUP(AK35,{$D35:$AI35;$D$1:$AI$1},2,false) -> Charlene | AN35: =count(D35:AI35) -> 4
A36: <?> | B36: Preston | F36: 375 | K36: 495 | Y36: 730 | AC36: 490 | AJ36: =MIN($D36:$AI36) -> 375 | AK36: =MAX($D36:$AI36) -> 730 | AL36: =HLOOKUP(AJ36,{$D36:$AI36;$D$1:$AI$1},2,false) -> Allyn | AM36: =HLOOKUP(AK36,{$D36:$AI36;$D$1:$AI$1},2,false) -> Nancy | AN36: =count(D36:AI36) -> 4
A37: <?> | B37: Superior | I37: 535 | K37: 590 | L37: 635 | Q37: 905 | Y37: 480 | AJ37: =MIN($D37:$AI37) -> 480 | AK37: =MAX($D37:$AI37) -> 905 | AL37: =HLOOKUP(AJ37,{$D37:$AI37;$D$1:$AI$1},2,false) -> Nancy | AM37: =HLOOKUP(AK37,{$D37:$AI37;$D$1:$AI$1},2,false) -> Jeff M | AN37: =count(D37:AI37) -> 5
A38: <?> | B38: Superior | I38: 840 | K38: 725 | L38: 950 | Y38: 150 | AB38: 565 | AJ38: =MIN($D38:$AI38) -> 150 | AK38: =MAX($D38:$AI38) -> 950 | AL38: =HLOOKUP(AJ38,{$D38:$AI38;$D$1:$AI$1},2,false) -> Nancy | AM38: =HLOOKUP(AK38,{$D38:$AI38;$D$1:$AI$1},2,false) -> Debby | AN38: =count(D38:AI38) -> 5
A39: <?> | B39: Preston | I39: 635 | K39: 665 | L39: 500 | Y39: 520 | AJ39: =MIN($D39:$AI39) -> 500 | AK39: =MAX($D39:$AI39) -> 665 | AL39: =HLOOKUP(AJ39,{$D39:$AI39;$D$1:$AI$1},2,false) -> Debby | AM39: =HLOOKUP(AK39,{$D39:$AI39;$D$1:$AI$1},2,false) -> David | AN39: =count(D39:AI39) -> 4
A40: <?> | B40: Preston | C40: Yes | I40: 235 | K40: 265 | L40: 270 | Q40: 110 | Y40: 360 | AJ40: =MIN($D40:$AI40) -> 110 | AK40: =MAX($D40:$AI40) -> 360 | AL40: =HLOOKUP(AJ40,{$D40:$AI40;$D$1:$AI$1},2,false) -> Jeff M | AM40: =HLOOKUP(AK40,{$D40:$AI40;$D$1:$AI$1},2,false) -> Nancy | AN40: =count(D40:AI40) -> 5
...

Sheet Leaders (dont edit)
A1: {=INDEX('Stats (dont edit)'!1:1,0)} -> Name | B1: Games | C1: Wins | D1: Win % | E1: Losses | F1: Loss % | G1: Lowest | H1: Highest | I1: Avg | J1: All Time | K1: Rank | L1: Score
A2: =IFERROR(__xludf.DUMMYFUNCTION("SORT(FILTER('Stats (dont edit)'!A2:L1000,'Stats (dont edit)'!D2:D1000<>""""),11,TRUE)"),"Karenina") -> Karenina | B2: =IFERROR(__xludf.DUMMYFUNCTION("""COMPUTED_VALUE"""),18.0) -> 18 | C2: =IFERROR(__xludf.DUMMYFUNCTION("""COMPUTED_VALUE"""),6.0) -> 6 | D2: =IFERROR(__xludf.DUMMYFUNCTION("""COMPUTED_VALUE"""),0.3333333333333333) -> 0.33333333 | E2: =IFERROR(__xludf.DUMMYFUNCTION("""COMPUTED_VALUE"""),2.0) -> 2 | F2: =IFERROR(__xludf.DUMMYFUNCTION("""COMPUTED_VALUE"""),0.1111111111111111) -> 0.11111111 | G2: =IFERROR(__xludf.DUMMYFUNCTION("""COMPUTED_VALUE"""),60.0) -> 60 | H2: =IFERROR(__xludf.DUMMYFUNCTION("""COMPUTED_VALUE"""),800.0) -> 800 | I2: =IFERROR(__xludf.DUMMYFUNCTION("""COMPUTED_VALUE"""),359.44444444444446) -> 359.44444 | J2: =IFERROR(__xludf.DUMMYFUNCTION("""COMPUTED_VALUE"""),6470.0) -> 6470 | K2: =IFERROR(__xludf.DUMMYFUNCTION("""COMPUTED_VALUE"""),1.0) -> 1 | L2: =IFERROR(__xludf.DUMMYFUNCTION("""COMPUTED_VALUE"""),1.5833333333333333) -> 1.5833333
A3: =IFERROR(__xludf.DUMMYFUNCTION("""COMPUTED_VALUE"""),"Jeff M") -> Jeff M | B3: =IFERROR(__xludf.DUMMYFUNCTION("""COMPUTED_VALUE"""),81.0) -> 81 | C3: =IFERROR(__xludf.DUMMYFUNCTION("""COMPUTED_VALUE"""),23.0) -> 23 | D3: =IFERROR(__xludf.DUMMYFUNCTION("""COMPUTED_VALUE"""),0.2839506172839506) -> 0.28395062 | E3: =IFERROR(__xludf.DUMMYFUNCTION("""COMPUTED_VALUE"""),26.0) -> 26 | F3: =IFERROR(__xludf.DUMMYFUNCTION("""COMPUTED_VALUE"""),0.32098765432098764) -> 0.32098765 | G3: =IFERROR(__xludf.DUMMYFUNCTION("""COMPUTED_VALUE"""),15.0) -> 15 | H3: =IFERROR(__xludf.DUMMYFUNCTION("""COMPUTED_VALUE"""),1310.0) -> 1310 | I3: =IFERROR(__xludf.DUMMYFUNCTION("""COMPUTED_VALUE"""),428.4567901234568) -> 428.45679 | J3: =IFERROR(__xludf.DUMMYFUNCTION("""COMPUTED_VALUE"""),34705.0) -> 34705 | K3: =IFERROR(__xludf.DUMMYFUNCTION("""COMPUTED_VALUE"""),2.0) -> 2 | L3: =IFERROR(__xludf.DUMMYFUNCTION("""COMPUTED_VALUE"""),1.156683432403597) -> 1.1566834
A4: =IFERROR(__xludf.DUMMYFUNCTION("""COMPUTED_VALUE"""),"David") -> David | B4: =IFERROR(__xludf.DUMMYFUNCTION("""COMPUTED_VALUE"""),493.0) -> 493 | C4: =IFERROR(__xludf.DUMMYFUNCTION("""COMPUTED_VALUE"""),148.0) -> 148 | D4: =IFERROR(__xludf.DUMMYFUNCTION("""COMPUTED_VALUE"""),0.3002028397565923) -> 0.30020284 | E4: =IFERROR(__xludf.DUMMYFUNCTION("""COMPUTED_VALUE"""),98.0) -> 98 | F4: =IFERROR(__xludf.DUMMYFUNCTION("""COMPUTED_VALUE"""),0.19878296146044624) -> 0.19878296 | G4: =IFERROR(__xludf.DUMMYFUNCTION("""COMPUTED_VALUE"""),5.0) -> 5 | H4: =IFERROR(__xludf.DUMMYFUNCTION("""COMPUTED_VALUE"""),1080.0) -> 1080 | I4: =IFERROR(__xludf.DUMMYFUNCTION("""COMPUTED_VALUE"""),396.8762677484787) -> 396.87627 | J4: =IFERROR(__xludf.DUMMYFUNCTION("""COMPUTED_VALUE"""),195660.0) -> 195660 | K4: =IFERROR(__xludf.DUMMYFUNCTION("""COMPUTED_VALUE"""),3.0) -> 3 | L4: =IFERROR(__xludf.DUMMYFUNCTION("""COMPUTED_VALUE"""),1.1383877325148426) -> 1.1383877
A5: =IFERROR(__xludf.DUMMYFUNCTION("""COMPUTED_VALUE"""),"Karen") -> Karen | B5: =IFERROR(__xludf.DUMMYFUNCTION("""COMPUTED_VALUE"""),34.0) -> 34 | C5: =IFERROR(__xludf.DUMMYFUNCTION("""COMPUTED_VALUE"""),9.0) -> 9 | D5: =IFERROR(__xludf.DUMMYFUNCTION("""COMPUTED_VALUE"""),0.2647058823529412) -> 0.26470588 | E5: =IFERROR(__xludf.DUMMYFUNCTION("""COMPUTED_VALUE"""),12.0) -> 12 | F5: =IFERROR(__xludf.DUMMYFUNCTION("""COMPUTED_VALUE"""),0.35294117647058826) -> 0.35294118 | G5: =IFERROR(__xludf.DUMMYFUNCTION("""COMPUTED_VALUE"""),55.0) -> 55 | H5: =IFERROR(__xludf.DUMMYFUNCTION("""COMPUTED_VALUE"""),890.0) -> 890 | I5: =IFERROR(__xludf.DUMMYFUNCTION("""COMPUTED_VALUE"""),430.1470588235294) -> 430.14706 | J5: =IFERROR(__xludf.DUMMYFUNCTION("""COMPUTED_VALUE"""),14625.0) -> 14625 | K5: =IFERROR(__xludf.DUMMYFUNCTION("""COMPUTED_VALUE"""),4.0) -> 4 | L5: =IFERROR(__xludf.DUMMYFUNCTION("""COMPUTED_VALUE"""),1.1038062283737025) -> 1.1038062
A6: =IFERROR(__xludf.DUMMYFUNCTION("""COMPUTED_VALUE"""),"Charlene") -> Charlene | B6: =IFERROR(__xludf.DUMMYFUNCTION("""COMPUTED_VALUE"""),342.0) -> 342 | C6: =IFERROR(__xludf.DUMMYFUNCTION("""COMPUTED_VALUE"""),89.0) -> 89 | D6: =IFERROR(__xludf.DUMMYFUNCTION("""COMPUTED_VALUE"""),0.260233918128655) -> 0.26023392 | E6: =IFERROR(__xludf.DUMMYFUNCTION("""COMPUTED_VALUE"""),75.0) -> 75 | F6: =IFERROR(__xludf.DUMMYFUNCTION("""COMPUTED_VALUE"""),0.21929824561403508) -> 0.21929825 | G6: =IFERROR(__xludf.DUMMYFUNCTION("""COMPUTED_VALUE"""),45.0) -> 45 | H6: =IFERROR(__xludf.DUMMYFUNCTION("""COMPUTED_VALUE"""),1020.0) -> 1020 | I6: =IFERROR(__xludf.DUMMYFUNCTION("""COMPUTED_VALUE"""),416.9590643274854) -> 416.95906 | J6: =IFERROR(__xludf.DUMMYFUNCTION("""COMPUTED_VALUE"""),142600.0) -> 142600 | K6: =IFERROR(__xludf.DUMMYFUNCTION("""COMPUTED_VALUE"""),5.0) -> 5 | L6: =IFERROR(__xludf.DUMMYFUNCTION("""COMPUTED_VALUE"""),1.0734585000512977) -> 1.0734585
A7: =IFERROR(__xludf.DUMMYFUNCTION("""COMPUTED_VALUE"""),"Nancy") -> Nancy | B7: =IFERROR(__xludf.DUMMYFUNCTION("""COMPUTED_VALUE"""),514.0) -> 514 | C7: =IFERROR(__xludf.DUMMYFUNCTION("""COMPUTED_VALUE"""),137.0) -> 137 | D7: =IFERROR(__xludf.DUMMYFUNCTION("""COMPUTED_VALUE"""),0.26653696498054474) -> 0.26653697 | E7: =IFERROR(__xludf.DUMMYFUNCTION("""COMPUTED_VALUE"""),114.0) -> 114 | F7: =IFERROR(__xludf.DUMMYFUNCTION("""COMPUTED_VALUE"""),0.22178988326848248) -> 0.22178988 | G7: =IFERROR(__xludf.DUMMYFUNCTION("""COMPUTED_VALUE"""),30.0) -> 30 | H7: =IFERROR(__xludf.DUMMYFUNCTION("""COMPUTED_VALUE"""),1100.0) -> 1100 | I7: =IFERROR(__xludf.DUMMYFUNCTION("""COMPUTED_VALUE"""),406.03891050583655) -> 406.03891 | J7: =IFERROR(__xludf.DUMMYFUNCTION("""COMPUTED_VALUE"""),208704.0) -> 208704 | K7: =IFERROR(__xludf.DUMMYFUNCTION("""COMPUTED_VALUE"""),6.0) -> 6 | L7: =IFERROR(__xludf.DUMMYFUNCTION("""COMPUTED_VALUE"""),1.0275552998531394) -> 1.0275553
A8: =IFERROR(__xludf.DUMMYFUNCTION("""COMPUTED_VALUE"""),"Debby") -> Debby | B8: =IFERROR(__xludf.DUMMYFUNCTION("""COMPUTED_VALUE"""),184.0) -> 184 | C8: =IFERROR(__xludf.DUMMYFUNCTION("""COMPUTED_VALUE"""),43.0) -> 43 | D8: =IFERROR(__xludf.DUMMYFUNCTION("""COMPUTED_VALUE"""),0.23369565217391305) -> 0.23369565 | E8: =IFERROR(__xludf.DUMMYFUNCTION("""COMPUTED_VALUE"""),55.0) -> 55 | F8: =IFERROR(__xludf.DUMMYFUNCTION("""COMPUTED_VALUE"""),0.29891304347826086) -> 0.29891304 | G8: =IFERROR(__xludf.DUMMYFUNCTION("""COMPUTED_VALUE"""),25.0) -> 25 | H8: =IFERROR(__xludf.DUMMYFUNCTION("""COMPUTED_VALUE"""),1025.0) -> 1025 | I8: =IFERROR(__xludf.DUMMYFUNCTION("""COMPUTED_VALUE"""),459.1304347826087) -> 459.13043 | J8: =IFERROR(__xludf.DUMMYFUNCTION("""COMPUTED_VALUE"""),84480.0) -> 84480 | K8: =IFERROR(__xludf.DUMMYFUNCTION("""COMPUTED_VALUE"""),7.0) -> 7 | L8: =IFERROR(__xludf.DUMMYFUNCTION("""COMPUTED_VALUE"""),0.9771089319470699) -> 0.97710893
A9: =IFERROR(__xludf.DUMMYFUNCTION("""COMPUTED_VALUE"""),"Sally") -> Sally | B9: =IFERROR(__xludf.DUMMYFUNCTION("""COMPUTED_VALUE"""),207.0) -> 207 | C9: =IFERROR(__xludf.DUMMYFUNCTION("""COMPUTED_VALUE"""),45.0) -> 45 | D9: =IFERROR(__xludf.DUMMYFUNCTION("""COMPUTED_VALUE"""),0.21739130434782608) -> 0.2173913 | E9: =IFERROR(__xludf.DUMMYFUNCTION("""COMPUTED_VALUE"""),78.0) -> 78 | F9: =IFERROR(__xludf.DUMMYFUNCTION("""COMPUTED_VALUE"""),0.37681159420289856) -> 0.37681159 | G9: =IFERROR(__xludf.DUMMYFUNCTION("""COMPUTED_VALUE"""),40.0) -> 40 | H9: =IFERROR(__xludf.DUMMYFUNCTION("""COMPUTED_VALUE"""),1185.0) -> 1185 | I9: =IFERROR(__xludf.DUMMYFUNCTION("""COMPUTED_VALUE"""),446.7149758454106) -> 446.71498 | J9: =IFERROR(__xludf.DUMMYFUNCTION("""COMPUTED_VALUE"""),92470.0) -> 92470 | K9: =IFERROR(__xludf.DUMMYFUNCTION("""COMPUTED_VALUE"""),8.0) -> 8 | L9: =IFERROR(__xludf.DUMMYFUNCTION("""COMPUTED_VALUE"""),0.7661088940231977) -> 0.76610889
A10: =IFERROR(__xludf.DUMMYFUNCTION("""COMPUTED_VALUE"""),"Sara") -> Sara | B10: =IFERROR(__xludf.DUMMYFUNCTION("""COMPUTED_VALUE"""),26.0) -> 26 | C10: =IFERROR(__xludf.DUMMYFUNCTION("""COMPUTED_VALUE"""),5.0) -> 5 | D10: =IFERROR(__xludf.DUMMYFUNCTION("""COMPUTED_VALUE"""),0.19230769230769232) -> 0.19230769 | E10: =IFERROR(__xludf.DUMMYFUNCTION("""COMPUTED_VALUE"""),7.0) -> 7 | F10: =IFERROR(__xludf.DUMMYFUNCTION("""COMPUTED_VALUE"""),0.2692307692307692) -> 0.26923077 | G10: =IFERROR(__xludf.DUMMYFUNCTION("""COMPUTED_VALUE"""),45.0) -> 45 | H10: =IFERROR(__xludf.DUMMYFUNCTION("""COMPUTED_VALUE"""),940.0) -> 940 | I10: =IFERROR(__xludf.DUMMYFUNCTION("""COMPUTED_VALUE"""),367.6923076923077) -> 367.69231 | J10: =IFERROR(__xludf.DUMMYFUNCTION("""COMPUTED_VALUE"""),9560.0) -> 9560 | K10: =IFERROR(__xludf.DUMMYFUNCTION("""COMPUTED_VALUE"""),9.0) -> 9 | L10: =IFERROR(__xludf.DUMMYFUNCTION("""COMPUTED_VALUE"""),0.6923076923076923) -> 0.69230769
A11: =IFERROR(__xludf.DUMMYFUNCTION("""COMPUTED_VALUE"""),"Sandy") -> Sandy | B11: =IFERROR(__xludf.DUMMYFUNCTION("""COMPUTED_VALUE"""),138.0) -> 138 | C11: =IFERROR(__xludf.DUMMYFUNCTION("""COMPUTED_VALUE"""),21.0) -> 21 | D11: =IFERROR(__xludf.DUMMYFUNCTION("""COMPUTED_VALUE"""),0.15217391304347827) -> 0.15217391 | E11: =IFERROR(__xludf.DUMMYFUNCTION("""COMPUTED_VALUE"""),43.0) -> 43 | F11: =IFERROR(__xludf.DUMMYFUNCTION("""COMPUTED_VALUE"""),0.3115942028985507) -> 0.3115942 | G11: =IFERROR(__xludf.DUMMYFUNCTION("""COMPUTED_VALUE"""),40.0) -> 40 | H11: =IFERROR(__xludf.DUMMYFUNCTION("""COMPUTED_VALUE"""),1120.0) -> 1120 | I11: =IFERROR(__xludf.DUMMYFUNCTION("""COMPUTED_VALUE"""),501.8840579710145) -> 501.88406 | J11: =IFERROR(__xludf.DUMMYFUNCTION("""COMPUTED_VALUE"""),69260.0) -> 69260 | K11: =IFERROR(__xludf.DUMMYFUNCTION("""COMPUTED_VALUE"""),10.0) -> 10 | L11: =IFERROR(__xludf.DUMMYFUNCTION("""COMPUTED_VALUE"""),0.6570048309178744) -> 0.65700483

Sheet Stats (dont edit)
A1: Name | B1: Games | C1: Wins | D1: Win % | E1: Losses | F1: Loss % | G1: Lowest | H1: Highest | I1: Avg | J1: All Time | K1: Rank | L1: Score
A2: =('Pivot (dont edit)'!A4) -> aa | B2: =count('Pivot (dont edit)'!4:4) -> 1 | C2: =COUNTIF('Raw Games'!AL:AL,$A2) -> 0 | D2: =IF($B2>'Constants (dont edit)'!$B$3,C2/$B2,"") | E2: =COUNTIF('Raw Games'!AM:AM,$A2) -> 0 | F2: =IF($B2>'Constants (dont edit)'!$B$3,E2/$B2,"") | G2: =MIN('Pivot (dont edit)'!4:4) -> 150 | H2: =MAX('Pivot (dont edit)'!4:4) -> 150 | I2: =if(AND(B2>='Constants (dont edit)'!$B$4,SUM('Pivot (dont edit)'!4:4)>0), AVERAGE('Pivot (dont edit)'!4:4), "") | J2: =sum('Pivot (dont edit)'!4:4) -> 150 | K2: =RANK(L2,L:L) -> 11 | L2: =IF($B2>'Constants (dont edit)'!$B$3,(SUMIF('Raw Games'!AL:AL,$A2,'Raw Games'!AN:AN)-SUMIF('Raw Games'!AM:AM,$A2,'Raw Games'!AN:AN)/B2)/B2,0) -> 0
A3: =('Pivot (dont edit)'!A5) -> Alizé | B3: =count('Pivot (dont edit)'!5:5) -> 1 | C3: =COUNTIF('Raw Games'!AL:AL,$A3) -> 0 | D3: =IF($B3>'Constants (dont edit)'!$B$3,C3/$B3,"") | E3: =COUNTIF('Raw Games'!AM:AM,$A3) -> 0 | F3: =IF($B3>'Constants (dont edit)'!$B$3,E3/$B3,"") | G3: =MIN('Pivot (dont edit)'!5:5) -> 355 | H3: =MAX('Pivot (dont edit)'!5:5) -> 355 | I3: =if(AND(B3>='Constants (dont edit)'!$B$4,SUM('Pivot (dont edit)'!5:5)>0), AVERAGE('Pivot (dont edit)'!5:5), "") | J3: =sum('Pivot (dont edit)'!5:5) -> 355 | K3: =RANK(L3,L:L) -> 11 | L3: =IF($B3>'Constants (dont edit)'!$B$3,(SUMIF('Raw Games'!AL:AL,$A3,'Raw Games'!AN:AN)-SUMIF('Raw Games'!AM:AM,$A3,'Raw Games'!AN:AN)/B3)/B3,0) -> 0
A4: =('Pivot (dont edit)'!A6) -> Allyn | B4: =count('Pivot (dont edit)'!6:6) -> 9 | C4: =COUNTIF('Raw Games'!AL:AL,$A4) -> 2 | D4: =IF($B4>'Constants (dont edit)'!$B$3,C4/$B4,"") | E4: =COUNTIF('Raw Games'!AM:AM,$A4) -> 3 | F4: =IF($B4>'Constants (dont edit)'!$B$3,E4/$B4,"") | G4: =MIN('Pivot (dont edit)'!6:6) -> 80 | H4: =MAX('Pivot (dont edit)'!6:6) -> 750 | I4: =if(AND(B4>='Constants (dont edit)'!$B$4,SUM('Pivot (dont edit)'!6:6)>0), AVERAGE('Pivot (dont edit)'!6:6), "") -> 378.88889 | J4: =sum('Pivot (dont edit)'!6:6) -> 3410 | K4: =RANK(L4,L:L) -> 11 | L4: =IF($B4>'Constants (dont edit)'!$B$3,(SUMIF('Raw Games'!AL:AL,$A4,'Raw Games'!AN:AN)-SUMIF('Raw Games'!AM:AM,$A4,'Raw Games'!AN:AN)/B4)/B4,0) -> 0
A5: =('Pivot (dont edit)'!A7) -> Bo | B5: =count('Pivot (dont edit)'!7:7) -> 1 | C5: =COUNTIF('Raw Games'!AL:AL,$A5) -> 0 | D5: =IF($B5>'Constants (dont edit)'!$B$3,C5/$B5,"") | E5: =COUNTIF('Raw Games'!AM:AM,$A5) -> 0 | F5: =IF($B5>'Constants (dont edit)'!$B$3,E5/$B5,"") | G5: =MIN('Pivot (dont edit)'!7:7) -> 390 | H5: =MAX('Pivot (dont edit)'!7:7) -> 390 | I5: =if(AND(B5>='Constants (dont edit)'!$B$4,SUM('Pivot (dont edit)'!7:7)>0), AVERAGE('Pivot (dont edit)'!7:7), "") | J5: =sum('Pivot (dont edit)'!7:7) -> 390 | K5: =RANK(L5,L:L) -> 11 | L5: =IF($B5>'Constants (dont edit)'!$B$3,(SUMIF('Raw Games'!AL:AL,$A5,'Raw Games'!AN:AN)-SUMIF('Raw Games'!AM:AM,$A5,'Raw Games'!AN:AN)/B5)/B5,0) -> 0
A6: =('Pivot (dont edit)'!A8) -> Candace | B6: =count('Pivot (dont edit)'!8:8) -> 3 | C6: =COUNTIF('Raw Games'!AL:AL,$A6) -> 1 | D6: =IF($B6>'Constants (dont edit)'!$B$3,C6/$B6,"") | E6: =COUNTIF('Raw Games'!AM:AM,$A6) -> 0 | F6: =IF($B6>'Constants (dont edit)'!$B$3,E6/$B6,"") | G6: =MIN('Pivot (dont edit)'!8:8) -> 170 | H6: =MAX('Pivot (dont edit)'!8:8) -> 540 | I6: =if(AND(B6>='Constants (dont edit)'!$B$4,SUM('Pivot (dont edit)'!8:8)>0), AVERAGE('Pivot (dont edit)'!8:8), "") -> 376.66667 | J6: =sum('Pivot (dont edit)'!8:8) -> 1130 | K6: =RANK(L6,L:L) -> 11 | L6: =IF($B6>'Constants (dont edit)'!$B$3,(SUMIF('Raw Games'!AL:AL,$A6,'Raw Games'!AN:AN)-SUMIF('Raw Games'!AM:AM,$A6,'Raw Games'!AN:AN)/B6)/B6,0) -> 0
A7: =('Pivot (dont edit)'!A9) -> Charlene | B7: =count('Pivot (dont edit)'!9:9) -> 342 | C7: =COUNTIF('Raw Games'!AL:AL,$A7) -> 89 | D7: =IF($B7>'Constants (dont edit)'!$B$3,C7/$B7,"") -> 0.26023392 | E7: =COUNTIF('Raw Games'!AM:AM,$A7) -> 75 | F7: =IF($B7>'Constants (dont edit)'!$B$3,E7/$B7,"") -> 0.21929825 | G7: =MIN('Pivot (dont edit)'!9:9) -> 45 | H7: =MAX('Pivot (dont edit)'!9:9) -> 1020 | I7: =if(AND(B7>='Constants (dont edit)'!$B$4,SUM('Pivot (dont edit)'!9:9)>0), AVERAGE('Pivot (dont edit)'!9:9), "") -> 416.95906 | J7: =sum('Pivot (dont edit)'!9:9) -> 142600 | K7: =RANK(L7,L:L) -> 5 | L7: =IF($B7>'Constants (dont edit)'!$B$3,(SUMIF('Raw Games'!AL:AL,$A7,'Raw Games'!AN:AN)-SUMIF('Raw Games'!AM:AM,$A7,'Raw Games'!AN:AN)/B7)/B7,0) -> 1.0734585
A8: =('Pivot (dont edit)'!A10) -> Clelia | B8: =count('Pivot (dont edit)'!10:10) -> 3 | C8: =COUNTIF('Raw Games'!AL:AL,$A8) -> 0 | D8: =IF($B8>'Constants (dont edit)'!$B$3,C8/$B8,"") | E8: =COUNTIF('Raw Games'!AM:AM,$A8) -> 1 | F8: =IF($B8>'Constants (dont edit)'!$B$3,E8/$B8,"") | G8: =MIN('Pivot (dont edit)'!10:10) -> 205 | H8: =MAX('Pivot (dont edit)'!10:10) -> 645 | I8: =if(AND(B8>='Constants (dont edit)'!$B$4,SUM('Pivot (dont edit)'!10:10)>0), AVERAGE('Pivot (dont edit)'!10:10), "") -> 395 | J8: =sum('Pivot (dont edit)'!10:10) -> 1185 | K8: =RANK(L8,L:L) -> 11 | L8: =IF($B8>'Constants (dont edit)'!$B$3,(SUMIF('Raw Games'!AL:AL,$A8,'Raw Games'!AN:AN)-SUMIF('Raw Games'!AM:AM,$A8,'Raw Games'!AN:AN)/B8)/B8,0) -> 0
A9: =('Pivot (dont edit)'!A11) -> David | B9: =count('Pivot (dont edit)'!11:11) -> 493 | C9: =COUNTIF('Raw Games'!AL:AL,$A9) -> 148 | D9: =IF($B9>'Constants (dont edit)'!$B$3,C9/$B9,"") -> 0.30020284 | E9: =COUNTIF('Raw Games'!AM:AM,$A9) -> 98 | F9: =IF($B9>'Constants (dont edit)'!$B$3,E9/$B9,"") -> 0.19878296 | G9: =MIN('Pivot (dont edit)'!11:11) -> 5 | H9: =MAX('Pivot (dont edit)'!11:11) -> 1080 | I9: =if(AND(B9>='Constants (dont edit)'!$B$4,SUM('Pivot (dont edit)'!11:11)>0), AVERAGE('Pivot (dont edit)'!11:11), "") -> 396.87627 | J9: =sum('Pivot (dont edit)'!11:11) -> 195660 | K9: =RANK(L9,L:L) -> 3 | L9: =IF($B9>'Constants (dont edit)'!$B$3,(SUMIF('Raw Games'!AL:AL,$A9,'Raw Games'!AN:AN)-SUMIF('Raw Games'!AM:AM,$A9,'Raw Games'!AN:AN)/B9)/B9,0) -> 1.1383877
A10: =('Pivot (dont edit)'!A12) -> Debby | B10: =count('Pivot (dont edit)'!12:12) -> 184 | C10: =COUNTIF('Raw Games'!AL:AL,$A10) -> 43 | D10: =IF($B10>'Constants (dont edit)'!$B$3,C10/$B10,"") -> 0.23369565 | E10: =COUNTIF('Raw Games'!AM:AM,$A10) -> 55 | F10: =IF($B10>'Constants (dont edit)'!$B$3,E10/$B10,"") -> 0.29891304 | G10: =MIN('Pivot (dont edit)'!12:12) -> 25 | H10: =MAX('Pivot (dont edit)'!12:12) -> 1025 | I10: =if(AND(B10>='Constants (dont edit)'!$B$4,SUM('Pivot (dont edit)'!12:12)>0), AVERAGE('Pivot (dont edit)'!12:12), "") -> 459.13043 | J10: =sum('Pivot (dont edit)'!12:12) -> 84480 | K10: =RANK(L10,L:L) -> 7 | L10: =IF($B10>'Constants (dont edit)'!$B$3,(SUMIF('Raw Games'!AL:AL,$A10,'Raw Games'!AN:AN)-SUMIF('Raw Games'!AM:AM,$A10,'Raw Games'!AN:AN)/B10)/B10,0) -> 0.97710893
A11: =('Pivot (dont edit)'!A13) -> Espy | B11: =count('Pivot (dont edit)'!13:13) -> 7 | C11: =COUNTIF('Raw Games'!AL:AL,$A11) -> 0 | D11: =IF($B11>'Constants (dont edit)'!$B$3,C11/$B11,"") | E11: =COUNTIF('Raw Games'!AM:AM,$A11) -> 3 | F11: =IF($B11>'Constants (dont edit)'!$B$3,E11/$B11,"") | G11: =MIN('Pivot (dont edit)'!13:13) -> 345 | H11: =MAX('Pivot (dont edit)'!13:13) -> 730 | I11: =if(AND(B11>='Constants (dont edit)'!$B$4,SUM('Pivot (dont edit)'!13:13)>0), AVERAGE('Pivot (dont edit)'!13:13), "") -> 562.14286 | J11: =sum('Pivot (dont edit)'!13:13) -> 3935 | K11: =RANK(L11,L:L) -> 11 | L11: =IF($B11>'Constants (dont edit)'!$B$3,(SUMIF('Raw Games'!AL:AL,$A11,'Raw Games'!AN:AN)-SUMIF('Raw Games'!AM:AM,$A11,'Raw Games'!AN:AN)/B11)/B11,0) -> 0
A12: =('Pivot (dont edit)'!A14) -> Jack | B12: =count('Pivot (dont edit)'!14:14) -> 6 | C12: =COUNTIF('Raw Games'!AL:AL,$A12) -> 1 | D12: =IF($B12>'Constants (dont edit)'!$B$3,C12/$B12,"") | E12: =COUNTIF('Raw Games'!AM:AM,$A12) -> 2 | F12: =IF($B12>'Constants (dont edit)'!$B$3,E12/$B12,"") | G12: =MIN('Pivot (dont edit)'!14:14) -> 300 | H12: =MAX('Pivot (dont edit)'!14:14) -> 630 | I12: =if(AND(B12>='Constants (dont edit)'!$B$4,SUM('Pivot (dont edit)'!14:14)>0), AVERAGE('Pivot (dont edit)'!14:14), "") -> 457.5 | J12: =sum('Pivot (dont edit)'!14:14) -> 2745 | K12: =RANK(L12,L:L) -> 11 | L12: =IF($B12>'Constants (dont edit)'!$B$3,(SUMIF('Raw Games'!AL:AL,$A12,'Raw Games'!AN:AN)-SUMIF('Raw Games'!AM:AM,$A12,'Raw Games'!AN:AN)/B12)/B12,0) -> 0
A13: =('Pivot (dont edit)'!A15) -> Jake | B13: =count('Pivot (dont edit)'!15:15) -> 1 | C13: =COUNTIF('Raw Games'!AL:AL,$A13) -> 0 | D13: =IF($B13>'Constants (dont edit)'!$B$3,C13/$B13,"") | E13: =COUNTIF('Raw Games'!AM:AM,$A13) -> 1 | F13: =IF($B13>'Constants (dont edit)'!$B$3,E13/$B13,"") | G13: =MIN('Pivot (dont edit)'!15:15) -> 620 | H13: =MAX('Pivot (dont edit)'!15:15) -> 620 | I13: =if(AND(B13>='Constants (dont edit)'!$B$4,SUM('Pivot (dont edit)'!15:15)>0), AVERAGE('Pivot (dont edit)'!15:15), "") | J13: =sum('Pivot (dont edit)'!15:15) -> 620 | K13: =RANK(L13,L:L) -> 11 | L13: =IF($B13>'Constants (dont edit)'!$B$3,(SUMIF('Raw Games'!AL:AL,$A13,'Raw Games'!AN:AN)-SUMIF('Raw Games'!AM:AM,$A13,'Raw Games'!AN:AN)/B13)/B13,0) -> 0
A14: =('Pivot (dont edit)'!A16) -> Jan | B14: =count('Pivot (dont edit)'!16:16) -> 3 | C14: =COUNTIF('Raw Games'!AL:AL,$A14) -> 1 | D14: =IF($B14>'Constants (dont edit)'!$B$3,C14/$B14,"") | E14: =COUNTIF('Raw Games'!AM:AM,$A14) -> 0 | F14: =IF($B14>'Constants (dont edit)'!$B$3,E14/$B14,"") | G14: =MIN('Pivot (dont edit)'!16:16) -> 425 | H14: =MAX('Pivot (dont edit)'!16:16) -> 755 | I14: =if(AND(B14>='Constants (dont edit)'!$B$4,SUM('Pivot (dont edit)'!16:16)>0), AVERAGE('Pivot (dont edit)'!16:16), "") -> 538.33333 | J14: =sum('Pivot (dont edit)'!16:16) -> 1615 | K14: =RANK(L14,L:L) -> 11 | L14: =IF($B14>'Constants (dont edit)'!$B$3,(SUMIF('Raw Games'!AL:AL,$A14,'Raw Games'!AN:AN)-SUMIF('Raw Games'!AM:AM,$A14,'Raw Games'!AN:AN)/B14)/B14,0) -> 0
A15: =('Pivot (dont edit)'!A17) -> Jeff M | B15: =count('Pivot (dont edit)'!17:17) -> 81 | C15: =COUNTIF('Raw Games'!AL:AL,$A15) -> 23 | D15: =IF($B15>'Constants (dont edit)'!$B$3,C15/$B15,"") -> 0.28395062 | E15: =COUNTIF('Raw Games'!AM:AM,$A15) -> 26 | F15: =IF($B15>'Constants (dont edit)'!$B$3,E15/$B15,"") -> 0.32098765 | G15: =MIN('Pivot (dont edit)'!17:17) -> 15 | H15: =MAX('Pivot (dont edit)'!17:17) -> 1310 | I15: =if(AND(B15>='Constants (dont edit)'!$B$4,SUM('Pivot (dont edit)'!17:17)>0), AVERAGE('Pivot (dont edit)'!17:17), "") -> 428.45679 | J15: =sum('Pivot (dont edit)'!17:17) -> 34705 | K15: =RANK(L15,L:L) -> 2 | L15: =IF($B15>'Constants (dont edit)'!$B$3,(SUMIF('Raw Games'!AL:AL,$A15,'Raw Games'!AN:AN)-SUMIF('Raw Games'!AM:AM,$A15,'Raw Games'!AN:AN)/B15)/B15,0) -> 1.1566834
A16: =('Pivot (dont edit)'!A18) -> Jeff P | B16: =count('Pivot (dont edit)'!18:18) -> 1 | C16: =COUNTIF('Raw Games'!AL:AL,$A16) -> 0 | D16: =IF($B16>'Constants (dont edit)'!$B$3,C16/$B16,"") | E16: =COUNTIF('Raw Games'!AM:AM,$A16) -> 1 | F16: =IF($B16>'Constants (dont edit)'!$B$3,E16/$B16,"") | G16: =MIN('Pivot (dont edit)'!18:18) -> 1155 | H16: =MAX('Pivot (dont edit)'!18:18) -> 1155 | I16: =if(AND(B16>='Constants (dont edit)'!$B$4,SUM('Pivot (dont edit)'!18:18)>0), AVERAGE('Pivot (dont edit)'!18:18), "") | J16: =sum('Pivot (dont edit)'!18:18) -> 1155 | K16: =RANK(L16,L:L) -> 11 | L16: =IF($B16>'Constants (dont edit)'!$B$3,(SUMIF('Raw Games'!AL:AL,$A16,'Raw Games'!AN:AN)-SUMIF('Raw Games'!AM:AM,$A16,'Raw Games'!AN:AN)/B16)/B16,0) -> 0
A17: =('Pivot (dont edit)'!A19) -> Jeremy | B17: =count('Pivot (dont edit)'!19:19) -> 2 | C17: =COUNTIF('Raw Games'!AL:AL,$A17) -> 1 | D17: =IF($B17>'Constants (dont edit)'!$B$3,C17/$B17,"") | E17: =COUNTIF('Raw Games'!AM:AM,$A17) -> 0 | F17: =IF($B17>'Constants (dont edit)'!$B$3,E17/$B17,"") | G17: =MIN('Pivot (dont edit)'!19:19) -> 400 | H17: =MAX('Pivot (dont edit)'!19:19) -> 645 | I17: =if(AND(B17>='Constants (dont edit)'!$B$4,SUM('Pivot (dont edit)'!19:19)>0), AVERAGE('Pivot (dont edit)'!19:19), "") | J17: =sum('Pivot (dont edit)'!19:19) -> 1045 | K17: =RANK(L17,L:L) -> 11 | L17: =IF($B17>'Constants (dont edit)'!$B$3,(SUMIF('Raw Games'!AL:AL,$A17,'Raw Games'!AN:AN)-SUMIF('Raw Games'!AM:AM,$A17,'Raw Games'!AN:AN)/B17)/B17,0) -> 0
A18: =('Pivot (dont edit)'!A20) -> Jordan | B18: =count('Pivot (dont edit)'!20:20) -> 2 | C18: =COUNTIF('Raw Games'!AL:AL,$A18) -> 0 | D18: =IF($B18>'Constants (dont edit)'!$B$3,C18/$B18,"") | E18: =COUNTIF('Raw Games'!AM:AM,$A18) -> 2 | F18: =IF($B18>'Constants (dont edit)'!$B$3,E18/$B18,"") | G18: =MIN('Pivot (dont edit)'!20:20) -> 675 | H18: =MAX('Pivot (dont edit)'!20:20) -> 905 | I18: =if(AND(B18>='Constants (dont edit)'!$B$4,SUM('Pivot (dont edit)'!20:20)>0), AVERAGE('Pivot (dont edit)'!20:20), "") | J18: =sum('Pivot (dont edit)'!20:20) -> 1580 | K18: =RANK(L18,L:L) -> 11 | L18: =IF($B18>'Constants (dont edit)'!$B$3,(SUMIF('Raw Games'!AL:AL,$A18,'Raw Games'!AN:AN)-SUMIF('Raw Games'!AM:AM,$A18,'Raw Games'!AN:AN)/B18)/B18,0) -> 0
A19: =('Pivot (dont edit)'!A21) -> Karenina | B19: =count('Pivot (dont edit)'!21:21) -> 18 | C19: =COUNTIF('Raw Games'!AL:AL,$A19) -> 6 | D19: =IF($B19>'Constants (dont edit)'!$B$3,C19/$B19,"") -> 0.33333333 | E19: =COUNTIF('Raw Games'!AM:AM,$A19) -> 2 | F19: =IF($B19>'Constants (dont edit)'!$B$3,E19/$B19,"") -> 0.11111111 | G19: =MIN('Pivot (dont edit)'!21:21) -> 60 | H19: =MAX('Pivot (dont edit)'!21:21) -> 800 | I19: =if(AND(B19>='Constants (dont edit)'!$B$4,SUM('Pivot (dont edit)'!21:21)>0), AVERAGE('Pivot (dont edit)'!21:21), "") -> 359.44444 | J19: =sum('Pivot (dont edit)'!21:21) -> 6470 | K19: =RANK(L19,L:L) -> 1 | L19: =IF($B19>'Constants (dont edit)'!$B$3,(SUMIF('Raw Games'!AL:AL,$A19,'Raw Games'!AN:AN)-SUMIF('Raw Games'!AM:AM,$A19,'Raw Games'!AN:AN)/B19)/B19,0) -> 1.5833333
A20: =('Pivot (dont edit)'!A22) -> Karen | B20: =count('Pivot (dont edit)'!22:22) -> 34 | C20: =COUNTIF('Raw Games'!AL:AL,$A20) -> 9 | D20: =IF($B20>'Constants (dont edit)'!$B$3,C20/$B20,"") -> 0.26470588 | E20: =COUNTIF('Raw Games'!AM:AM,$A20) -> 12 | F20: =IF($B20>'Constants (dont edit)'!$B$3,E20/$B20,"") -> 0.35294118 | G20: =MIN('Pivot (dont edit)'!22:22) -> 55 | H20: =MAX('Pivot (dont edit)'!22:22) -> 890 | I20: =if(AND(B20>='Constants (dont edit)'!$B$4,SUM('Pivot (dont edit)'!22:22)>0), AVERAGE('Pivot (dont edit)'!22:22), "") -> 430.14706 | J20: =sum('Pivot (dont edit)'!22:22) -> 14625 | K20: =RANK(L20,L:L) -> 4 | L20: =IF($B20>'Constants (dont edit)'!$B$3,(SUMIF('Raw Games'!AL:AL,$A20,'Raw Games'!AN:AN)-SUMIF('Raw Games'!AM:AM,$A20,'Raw Games'!AN:AN)/B20)/B20,0) -> 1.1038062
A21: =('Pivot (dont edit)'!A23) -> Kas | B21: =count('Pivot (dont edit)'!23:23) -> 6 | C21: =COUNTIF('Raw Games'!AL:AL,$A21) -> 0 | D21: =IF($B21>'Constants (dont edit)'!$B$3,C21/$B21,"") | E21: =COUNTIF('Raw Games'!AM:AM,$A21) -> 1 | F21: =IF($B21>'Constants (dont edit)'!$B$3,E21/$B21,"") | G21: =MIN('Pivot (dont edit)'!23:23) -> 365 | H21: =MAX('Pivot (dont edit)'!23:23) -> 830 | I21: =if(AND(B21>='Constants (dont edit)'!$B$4,SUM('Pivot (dont edit)'!23:23)>0), AVERAGE('Pivot (dont edit)'!23:23), "") -> 618.33333 | J21: =sum('Pivot (dont edit)'!23:23) -> 3710 | K21: =RANK(L21,L:L) -> 11 | L21: =IF($B21>'Constants (dont edit)'!$B$3,(SUMIF('Raw Games'!AL:AL,$A21,'Raw Games'!AN:AN)-SUMIF('Raw Games'!AM:AM,$A21,'Raw Games'!AN:AN)/B21)/B21,0) -> 0
A22: =('Pivot (dont edit)'!A24) -> Melissa | B22: =count('Pivot (dont edit)'!24:24) -> 5 | C22: =COUNTIF('Raw Games'!AL:AL,$A22) -> 1 | D22: =IF($B22>'Constants (dont edit)'!$B$3,C22/$B22,"") | E22: =COUNTIF('Raw Games'!AM:AM,$A22) -> 2 | F22: =IF($B22>'Constants (dont edit)'!$B$3,E22/$B22,"") | G22: =MIN('Pivot (dont edit)'!24:24) -> 215 | H22: =MAX('Pivot (dont edit)'!24:24) -> 740 | I22: =if(AND(B22>='Constants (dont edit)'!$B$4,SUM('Pivot (dont edit)'!24:24)>0), AVERAGE('Pivot (dont edit)'!24:24), "") -> 518 | J22: =sum('Pivot (dont edit)'!24:24) -> 2590 | K22: =RANK(L22,L:L) -> 11 | L22: =IF($B22>'Constants (dont edit)'!$B$3,(SUMIF('Raw Games'!AL:AL,$A22,'Raw Games'!AN:AN)-SUMIF('Raw Games'!AM:AM,$A22,'Raw Games'!AN:AN)/B22)/B22,0) -> 0
A23: =('Pivot (dont edit)'!A25) -> Nancy | B23: =count('Pivot (dont edit)'!25:25) -> 514 | C23: =COUNTIF('Raw Games'!AL:AL,$A23) -> 137 | D23: =IF($B23>'Constants (dont edit)'!$B$3,C23/$B23,"") -> 0.26653697 | E23: =COUNTIF('Raw Games'!AM:AM,$A23) -> 114 | F23: =IF($B23>'Constants (dont edit)'!$B$3,E23/$B23,"") -> 0.22178988 | G23: =MIN('Pivot (dont edit)'!25:25) -> 30 | H23: =MAX('Pivot (dont edit)'!25:25) -> 1100 | I23: =if(AND(B23>='Constants (dont edit)'!$B$4,SUM('Pivot (dont edit)'!25:25)>0), AVERAGE('Pivot (dont edit)'!25:25), "") -> 406.03891 | J23: =sum('Pivot (dont edit)'!25:25) -> 208704 | K23: =RANK(L23,L:L) -> 6 | L23: =IF($B23>'Constants (dont edit)'!$B$3,(SUMIF('Raw Games'!AL:AL,$A23,'Raw Games'!AN:AN)-SUMIF('Raw Games'!AM:AM,$A23,'Raw Games'!AN:AN)/B23)/B23,0) -> 1.0275553
A24: =('Pivot (dont edit)'!A26) -> Ray | B24: =count('Pivot (dont edit)'!26:26) -> 4 | C24: =COUNTIF('Raw Games'!AL:AL,$A24) -> 0 | D24: =IF($B24>'Constants (dont edit)'!$B$3,C24/$B24,"") | E24: =COUNTIF('Raw Games'!AM:AM,$A24) -> 1 | F24: =IF($B24>'Constants (dont edit)'!$B$3,E24/$B24,"") | G24: =MIN('Pivot (dont edit)'!26:26) -> 110 | H24: =MAX('Pivot (dont edit)'!26:26) -> 775 | I24: =if(AND(B24>='Constants (dont edit)'!$B$4,SUM('Pivot (dont edit)'!26:26)>0), AVERAGE('Pivot (dont edit)'!26:26), "") -> 412.5 | J24: =sum('Pivot (dont edit)'!26:26) -> 1650 | K24: =RANK(L24,L:L) -> 11 | L24: =IF($B24>'Constants (dont edit)'!$B$3,(SUMIF('Raw Games'!AL:AL,$A24,'Raw Games'!AN:AN)-SUMIF('Raw Games'!AM:AM,$A24,'Raw Games'!AN:AN)/B24)/B24,0) -> 0
A25: =('Pivot (dont edit)'!A27) -> Sally | B25: =count('Pivot (dont edit)'!27:27) -> 207 | C25: =COUNTIF('Raw Games'!AL:AL,$A25) -> 45 | D25: =IF($B25>'Constants (dont edit)'!$B$3,C25/$B25,"") -> 0.2173913 | E25: =COUNTIF('Raw Games'!AM:AM,$A25) -> 78 | F25: =IF($B25>'Constants (dont edit)'!$B$3,E25/$B25,"") -> 0.37681159 | G25: =MIN('Pivot (dont edit)'!27:27) -> 40 | H25: =MAX('Pivot (dont edit)'!27:27) -> 1185 | I25: =if(AND(B25>='Constants (dont edit)'!$B$4,SUM('Pivot (dont edit)'!27:27)>0), AVERAGE('Pivot (dont edit)'!27:27), "") -> 446.71498 | J25: =sum('Pivot (dont edit)'!27:27) -> 92470 | K25: =RANK(L25,L:L) -> 8 | L25: =IF($B25>'Constants (dont edit)'!$B$3,(SUMIF('Raw Games'!AL:AL,$A25,'Raw Games'!AN:AN)-SUMIF('Raw Games'!AM:AM,$A25,'Raw Games'!AN:AN)/B25)/B25,0) -> 0.76610889 | M25: =('Pivot (dont edit)'!M27) | N25: =count('Pivot (dont edit)'!27:27) -> 207 | O25: =COUNTIF('Raw Games'!AX:AX,$A25) -> 0 | P25: =IF($B25>'Constants (dont edit)'!$B$3,O25/$B25,"") -> 0 | Q25: =COUNTIF('Raw Games'!AY:AY,$A25) -> 0 | R25: =IF($B25>'Constants (dont edit)'!$B$3,Q25/$B25,"") -> 0 | S25: =MIN('Pivot (dont edit)'!27:27) -> 40 | T25: =MAX('Pivot (dont edit)'!27:27) -> 1185 | U25: =if(AND(N25>='Constants (dont edit)'!$B$4,SUM('Pivot (dont edit)'!27:27)>0), AVERAGE('Pivot (dont edit)'!27:27), "") -> 446.71498 | V25: =sum('Pivot (dont edit)'!27:27) -> 92470 | W25: =RANK(X25,X:X) -> 1 | X25: =IF($B25>'Constants (dont edit)'!$B$3,(SUMIF('Raw Games'!AX:AX,$A25,'Raw Games'!AZ:AZ)-SUMIF('Raw Games'!AY:AY,$A25,'Raw Games'!AZ:AZ)/N25)/N25,0) -> 0 | Y25: =('Pivot (dont edit)'!Y27) | Z25: =count('Pivot (dont edit)'!27:27) -> 207 | AA25: =COUNTIF('Raw Games'!BJ:BJ,$A25) -> 0 | AB25: =IF($B25>'Constants (dont edit)'!$B$3,AA25/$B25,"") -> 0 | AC25: =COUNTIF('Raw Games'!BK:BK,$A25) -> 0 | AD25: =IF($B25>'Constants (dont edit)'!$B$3,AC25/$B25,"") -> 0 | AE25: =MIN('Pivot (dont edit)'!27:27) -> 40 | AF25: =MAX('Pivot (dont edit)'!27:27) -> 1185
A26: =('Pivot (dont edit)'!A28) -> Sandy | B26: =count('Pivot (dont edit)'!28:28) -> 138 | C26: =COUNTIF('Raw Games'!AL:AL,$A26) -> 21 | D26: =IF($B26>'Constants (dont edit)'!$B$3,C26/$B26,"") -> 0.15217391 | E26: =COUNTIF('Raw Games'!AM:AM,$A26) -> 43 | F26: =IF($B26>'Constants (dont edit)'!$B$3,E26/$B26,"") -> 0.3115942 | G26: =MIN('Pivot (dont edit)'!28:28) -> 40 | H26: =MAX('Pivot (dont edit)'!28:28) -> 1120 | I26: =if(AND(B26>='Constants (dont edit)'!$B$4,SUM('Pivot (dont edit)'!28:28)>0), AVERAGE('Pivot (dont edit)'!28:28), "") -> 501.88406 | J26: =sum('Pivot (dont edit)'!28:28) -> 69260 | K26: =RANK(L26,L:L) -> 10 | L26: =IF($B26>'Constants (dont edit)'!$B$3,(SUMIF('Raw Games'!AL:AL,$A26,'Raw Games'!AN:AN)-SUMIF('Raw Games'!AM:AM,$A26,'Raw Games'!AN:AN)/B26)/B26,0) -> 0.65700483 | M26: =('Pivot (dont edit)'!M28) | N26: =count('Pivot (dont edit)'!28:28) -> 138 | O26: =COUNTIF('Raw Games'!AX:AX,$A26) -> 0 | P26: =IF($B26>'Constants (dont edit)'!$B$3,O26/$B26,"") -> 0 | Q26: =COUNTIF('Raw Games'!AY:AY,$A26) -> 0 | R26: =IF($B26>'Constants (dont edit)'!$B$3,Q26/$B26,"") -> 0 | S26: =MIN('Pivot (dont edit)'!28:28) -> 40 | T26: =MAX('Pivot (dont edit)'!28:28) -> 1120 | U26: =if(AND(N26>='Constants (dont edit)'!$B$4,SUM('Pivot (dont edit)'!28:28)>0), AVERAGE('Pivot (dont edit)'!28:28), "") -> 501.88406 | V26: =sum('Pivot (dont edit)'!28:28) -> 69260 | W26: =RANK(X26,X:X) -> 1 | X26: =IF($B26>'Constants (dont edit)'!$B$3,(SUMIF('Raw Games'!AX:AX,$A26,'Raw Games'!AZ:AZ)-SUMIF('Raw Games'!AY:AY,$A26,'Raw Games'!AZ:AZ)/N26)/N26,0) -> 0 | Y26: =('Pivot (dont edit)'!Y28) -> 895 | Z26: =count('Pivot (dont edit)'!28:28) -> 138 | AA26: =COUNTIF('Raw Games'!BJ:BJ,$A26) -> 0 | AB26: =IF($B26>'Constants (dont edit)'!$B$3,AA26/$B26,"") -> 0 | AC26: =COUNTIF('Raw Games'!BK:BK,$A26) -> 0 | AD26: =IF($B26>'Constants (dont edit)'!$B$3,AC26/$B26,"") -> 0 | AE26: =MIN('Pivot (dont edit)'!28:28) -> 40 | AF26: =MAX('Pivot (dont edit)'!28:28) -> 1120
A27: =('Pivot (dont edit)'!A29) -> Sara | B27: =count('Pivot (dont edit)'!29:29) -> 26 | C27: =COUNTIF('Raw Games'!AL:AL,$A27) -> 5 | D27: =IF($B27>'Constants (dont edit)'!$B$3,C27/$B27,"") -> 0.19230769 | E27: =COUNTIF('Raw Games'!AM:AM,$A27) -> 7 | F27: =IF($B27>'Constants (dont edit)'!$B$3,E27/$B27,"") -> 0.26923077 | G27: =MIN('Pivot (dont edit)'!29:29) -> 45 | H27: =MAX('Pivot (dont edit)'!29:29) -> 940 | I27: =if(AND(B27>='Constants (dont edit)'!$B$4,SUM('Pivot (dont edit)'!29:29)>0), AVERAGE('Pivot (dont edit)'!29:29), "") -> 367.69231 | J27: =sum('Pivot (dont edit)'!29:29) -> 9560 | K27: =RANK(L27,L:L) -> 9 | L27: =IF($B27>'Constants (dont edit)'!$B$3,(SUMIF('Raw Games'!AL:AL,$A27,'Raw Games'!AN:AN)-SUMIF('Raw Games'!AM:AM,$A27,'Raw Games'!AN:AN)/B27)/B27,0) -> 0.69230769 | M27: =('Pivot (dont edit)'!M29) | N27: =count('Pivot (dont edit)'!29:29) -> 26 | O27: =COUNTIF('Raw Games'!AX:AX,$A27) -> 0 | P27: =IF($B27>'Constants (dont edit)'!$B$3,O27/$B27,"") -> 0 | Q27: =COUNTIF('Raw Games'!AY:AY,$A27) -> 0 | R27: =IF($B27>'Constants (dont edit)'!$B$3,Q27/$B27,"") -> 0 | S27: =MIN('Pivot (dont edit)'!29:29) -> 45 | T27: =MAX('Pivot (dont edit)'!29:29) -> 940 | U27: =if(AND(N27>='Constants (dont edit)'!$B$4,SUM('Pivot (dont edit)'!29:29)>0), AVERAGE('Pivot (dont edit)'!29:29), "") -> 367.69231 | V27: =sum('Pivot (dont edit)'!29:29) -> 9560 | W27: =RANK(X27,X:X) -> 1 | X27: =IF($B27>'Constants (dont edit)'!$B$3,(SUMIF('Raw Games'!AX:AX,$A27,'Raw Games'!AZ:AZ)-SUMIF('Raw Games'!AY:AY,$A27,'Raw Games'!AZ:AZ)/N27)/N27,0) -> 0 | Y27: =('Pivot (dont edit)'!Y29) | Z27: =count('Pivot (dont edit)'!29:29) -> 26 | AA27: =COUNTIF('Raw Games'!BJ:BJ,$A27) -> 0 | AB27: =IF($B27>'Constants (dont edit)'!$B$3,AA27/$B27,"") -> 0 | AC27: =COUNTIF('Raw Games'!BK:BK,$A27) -> 0 | AD27: =IF($B27>'Constants (dont edit)'!$B$3,AC27/$B27,"") -> 0 | AE27: =MIN('Pivot (dont edit)'!29:29) -> 45 | AF27: =MAX('Pivot (dont edit)'!29:29) -> 940
A28: =('Pivot (dont edit)'!A30) -> Scott | B28: =count('Pivot (dont edit)'!30:30) -> 1 | C28: =COUNTIF('Raw Games'!AL:AL,$A28) -> 0 | D28: =IF($B28>'Constants (dont edit)'!$B$3,C28/$B28,"") | E28: =COUNTIF('Raw Games'!AM:AM,$A28) -> 1 | F28: =IF($B28>'Constants (dont edit)'!$B$3,E28/$B28,"") | G28: =MIN('Pivot (dont edit)'!30:30) -> 380 | H28: =MAX('Pivot (dont edit)'!30:30) -> 380 | I28: =if(AND(B28>='Constants (dont edit)'!$B$4,SUM('Pivot (dont edit)'!30:30)>0), AVERAGE('Pivot (dont edit)'!30:30), "") | J28: =sum('Pivot (dont edit)'!30:30) -> 380 | K28: =RANK(L28,L:L) -> 11 | L28: =IF($B28>'Constants (dont edit)'!$B$3,(SUMIF('Raw Games'!AL:AL,$A28,'Raw Games'!AN:AN)-SUMIF('Raw Games'!AM:AM,$A28,'Raw Games'!AN:AN)/B28)/B28,0) -> 0 | M28: =('Pivot (dont edit)'!M30) | N28: =count('Pivot (dont edit)'!30:30) -> 1 | O28: =COUNTIF('Raw Games'!AX:AX,$A28) -> 0 | P28: =IF($B28>'Constants (dont edit)'!$B$3,O28/$B28,"") | Q28: =COUNTIF('Raw Games'!AY:AY,$A28) -> 0 | R28: =IF($B28>'Constants (dont edit)'!$B$3,Q28/$B28,"") | S28: =MIN('Pivot (dont edit)'!30:30) -> 380 | T28: =MAX('Pivot (dont edit)'!30:30) -> 380 | U28: =if(AND(N28>='Constants (dont edit)'!$B$4,SUM('Pivot (dont edit)'!30:30)>0), AVERAGE('Pivot (dont edit)'!30:30), "") | V28: =sum('Pivot (dont edit)'!30:30) -> 380 | W28: =RANK(X28,X:X) -> 1 | X28: =IF($B28>'Constants (dont edit)'!$B$3,(SUMIF('Raw Games'!AX:AX,$A28,'Raw Games'!AZ:AZ)-SUMIF('Raw Games'!AY:AY,$A28,'Raw Games'!AZ:AZ)/N28)/N28,0) -> 0 | Y28: =('Pivot (dont edit)'!Y30) | Z28: =count('Pivot (dont edit)'!30:30) -> 1 | AA28: =COUNTIF('Raw Games'!BJ:BJ,$A28) -> 0 | AB28: =IF($B28>'Constants (dont edit)'!$B$3,AA28/$B28,"") | AC28: =COUNTIF('Raw Games'!BK:BK,$A28) -> 0 | AD28: =IF($B28>'Constants (dont edit)'!$B$3,AC28/$B28,"") | AE28: =MIN('Pivot (dont edit)'!30:30) -> 380 | AF28: =MAX('Pivot (dont edit)'!30:30) -> 380
A29: =('Pivot (dont edit)'!A31) -> Simon | B29: =count('Pivot (dont edit)'!31:31) -> 3 | C29: =COUNTIF('Raw Games'!AL:AL,$A29) -> 0 | D29: =IF($B29>'Constants (dont edit)'!$B$3,C29/$B29,"") | E29: =COUNTIF('Raw Games'!AM:AM,$A29) -> 0 | F29: =IF($B29>'Constants (dont edit)'!$B$3,E29/$B29,"") | G29: =MIN('Pivot (dont edit)'!31:31) -> 100 | H29: =MAX('Pivot (dont edit)'!31:31) -> 670 | I29: =if(AND(B29>='Constants (dont edit)'!$B$4,SUM('Pivot (dont edit)'!31:31)>0), AVERAGE('Pivot (dont edit)'!31:31), "") -> 458.33333 | J29: =sum('Pivot (dont edit)'!31:31) -> 1375 | K29: =RANK(L29,L:L) -> 11 | L29: =IF($B29>'Constants (dont edit)'!$B$3,(SUMIF('Raw Games'!AL:AL,$A29,'Raw Games'!AN:AN)-SUMIF('Raw Games'!AM:AM,$A29,'Raw Games'!AN:AN)/B29)/B29,0) -> 0 | M29: =('Pivot (dont edit)'!M31) | N29: =count('Pivot (dont edit)'!31:31) -> 3 | O29: =COUNTIF('Raw Games'!AX:AX,$A29) -> 0 | P29: =IF($B29>'Constants (dont edit)'!$B$3,O29/$B29,"") | Q29: =COUNTIF('Raw Games'!AY:AY,$A29) -> 0 | R29: =IF($B29>'Constants (dont edit)'!$B$3,Q29/$B29,"") | S29: =MIN('Pivot (dont edit)'!31:31) -> 100 | T29: =MAX('Pivot (dont edit)'!31:31) -> 670 | U29: =if(AND(N29>='Constants (dont edit)'!$B$4,SUM('Pivot (dont edit)'!31:31)>0), AVERAGE('Pivot (dont edit)'!31:31), "") -> 458.33333 | V29: =sum('Pivot (dont edit)'!31:31) -> 1375 | W29: =RANK(X29,X:X) -> 1 | X29: =IF($B29>'Constants (dont edit)'!$B$3,(SUMIF('Raw Games'!AX:AX,$A29,'Raw Games'!AZ:AZ)-SUMIF('Raw Games'!AY:AY,$A29,'Raw Games'!AZ:AZ)/N29)/N29,0) -> 0 | Y29: =('Pivot (dont edit)'!Y31) | Z29: =count('Pivot (dont edit)'!31:31) -> 3 | AA29: =COUNTIF('Raw Games'!BJ:BJ,$A29) -> 0 | AB29: =IF($B29>'Constants (dont edit)'!$B$3,AA29/$B29,"") | AC29: =COUNTIF('Raw Games'!BK:BK,$A29) -> 0 | AD29: =IF($B29>'Constants (dont edit)'!$B$3,AC29/$B29,"") | AE29: =MIN('Pivot (dont edit)'!31:31) -> 100 | AF29: =MAX('Pivot (dont edit)'!31:31) -> 670

Sheet Constants (dont edit)
A1: Name | B1: Value
A2: Constants
A3: Minimum Number of Games for stats | B3: 15
A4: Minimum Number of Games for avg | B4: 3
A5: Rank Factor | B5: 1000
A7: Global Stats
A8: Total Game Count | B8: =COUNTA('Raw Games'!A:A)-1 -> 538
A9: Full Game Count | B9: =B8-B10 -> 480
A10: Half Game Count | B10: =COUNTIF('Raw Games'!C:C,"=Yes") -> 58
A11: Overall average score | B11: =AVERAGE('Raw Games'!F:AI) -> 423.79322
A12: All time maximum score | B12: =MAX('Raw Games'!F:AI) -> 1310
A13: All time minimum score | B13: =MIN('Raw Games'!F:AI) -> 5
A14: Scores over 1000 | B14: =COUNTIF('Raw Games'!F:AI,">=1000") -> 18
A16: README
A17: 1. In 'Raw Games' sheet, be sure to keep Min, Max, Winner, Loser data filled downward at least as far as the game data rows.
A18: 2. In 'Raw Games' sheet, when winners and losers stop getting highlighted, you need to Edit > Paste Special > Conditional Formatting those rows and below after copying to clipboard the last highlighted row.
A19: 3. Adding a new person is a two stop process: 1) insert a column in the alphabetical location for the new person, and b) Navigate to "Stats" page and fill downward to reveal last person.
A20: 4. Inserting a new person whose name starts with A and is before the current first person is difficult because all the Conditions and Formulae will point to the column after. You will have to edit all of them.
A21: 5. To add new Game results, add them after the last row in the "Raw Games" sheet (curently at over 250 rows)
A22: 6. Once there are over 1001 rows in 'Raw Games' we will have to a) add Columns to the 'Pivot' sheet and b) Modify the TRANSPOSE function in Pivot!A:1 to include the additional columns.

Sheet Pivot (dont edit)
A1: {=TRANSPOSE('Raw Games'!1:1022)} -> Date | B1: <?> | C1: <?> | D1: <?> | E1: <?> | F1: <?> | G1: <?> | H1: <?> | I1: <?> | J1: <?> | K1: <?> | L1: <?> | M1: <?> | N1: <?> | O1: <?> | P1: <?> | Q1: <?> | R1: <?> | S1: <?> | T1: <?> | U1: <?> | V1: <?> | W1: <?> | X1: <?> | Y1: <?> | Z1: <?> | AA1: <?> | AB1: <?> | AC1: <?> | AD1: <?> | AE1: <?> | AF1: <?> | AG1: <?> | AH1: <?> | AI1: <?> | AJ1: <?> | AK1: <?> | AL1: <?> | AM1: <?> | AN1: <?> | AO1: <?> | AP1: <?> | AQ1: <?> | AR1: <?> | AS1: <?> | AT1: <?> | AU1: <?> | AV1: <?> | AW1: <?> | AX1: <?> | AY1: <?> | AZ1: <?> | BA1: <?> | BB1: <?> | BC1: <?> | BD1: <?> | BE1: <?> | BF1: <?> | BG1: <?> | BH1: <?> | BI1: <?> | BJ1: <?> | BK1: <?> | BL1: <?> | BM1: <?> | BN1: <?> | BO1: <?> | BP1: <?> | BQ1: <?> | BR1: <?> | BS1: <?> | BT1: <?> | BU1: <?> | BV1: <?> | BW1: <?> | BX1: <?> | BY1: <?> | BZ1: <?> | CA1: <?> | CB1: <?> | CC1: <?> | CD1: <?> | CE1: <?> | CF1: <?> | CG1: <?> | CH1: <?> | CI1: <?> | CJ1: <?> | CK1: <?> | CL1: <?> | CM1: <?> | CN1: <?> | CO1: <?> | CP1: <?> | CQ1: <?> | CR1: <?> | CS1: <?> | CT1: <?> | CU1: <?> | CV1: <?> | CW1: <?> | CX1: <?> | CY1: <?> | CZ1: <?> | DA1: <?> | DB1: <?> | DC1: <?> | DD1: <?> | DE1: <?> | DF1: <?> | DG1: <?> | DH1: <?> | DI1: <?> | DJ1: <?> | DK1: <?> | DL1: <?> | DM1: <?> | DN1: <?> | DO1: <?> | DP1: <?> | DQ1: <?> | DR1: <?> | DS1: <?> | DT1: <?> | DU1: <?> | DV1: <?> | DW1: <?> | DX1: 43485 | DY1: 44086 | DZ1: 44087 | EA1: 44089 | EB1: 44092 | EC1: 44098 | ED1: 44100 | EE1: 44107 | EF1: 44108 | EG1: 44112 | EH1: 44114 | EI1: 44121 | EJ1: 44122 | EK1: 44127 | EL1: 44129 | EM1: 44132 | EN1: 44135 | EO1: 44137 | EP1: 44140 | EQ1: 44142 | ER1: 44146 | ES1: 44148 | ET1: 44151 | EU1: 44156 | EV1: 44158 | EW1: 44164 | EX1: 44170 | EY1: 44170 | EZ1: 44173 | FA1: 44175 | FB1: 44176 | FC1: 44183 | FD1: 44186 | FE1: 44187 | FF1: 44200 | FG1: 44203 | FH1: 44204 | FI1: 44205 | FJ1: 44206 | FK1: 44210 | FL1: 44224 | FM1: 44225 | FN1: 44226 | FO1: 44239 | FP1: 44240 | FQ1: 44241 | FR1: 44242 | FS1: 44254 | FT1: 44256 | FU1: 44260 | FV1: 44264 | FW1: 44267 | FX1: 44272 | FY1: 44273 | FZ1: 44274 | GA1: 44276 | GB1: 44279 | GC1: 44281 | GD1: 44285 | GE1: 44288 | GF1: 44292 | GG1: 44293 | GH1: 44297 | GI1: 44297 | GJ1: 44297 | GK1: 44298 | GL1: 44299 | GM1: 44300 | GN1: 44302 | GO1: 44307 | GP1: 44312 | GQ1: 44318 | GR1: 44329 | GS1: 44342 | GT1: 44343 | GU1: 44344 | GV1: 44346 | GW1: 44347 | GX1: 44352 | GY1: 44362 | GZ1: 44370 | HA1: 44374 | HB1: 44375 | HC1: 44416 | HD1: 44422 | HE1: 44422 | HF1: 44423 | HG1: 44428 | HH1: 44437 | HI1: 44500 | HJ1: 44500 | HK1: 44538 | HL1: 44539 | HM1: 44562 | HN1: 44581 | HO1: 44595 | HP1: 44602 | HQ1: 44623 | HR1: 44664 | HS1: 44665 | HT1: 44673 | HU1: 44679 | HV1: 44681 | HW1: 44686 | HX1: 44688 | HY1: 44689 | HZ1: 44700 | IA1: 44702 | IB1: 44709 | IC1: 44710 | ID1: 44711 | IE1: 44712 | IF1: 44751 | IG1: 44756 | IH1: 44778 | II1: 44787 | IJ1: 44791 | IK1: 44793 | IL1: 44798 | IM1: 44815 | IN1: 44819 | IO1: 44836 | IP1: 44839 | IQ1: 44850 | IR1: 44852 | IS1: 44864 | IT1: 44870 | IU1: 44871 | IV1: 44875 | IW1: 44878 | IX1: 44880 | IY1: 44887 | IZ1: 44896 | JA1: 44903 | JB1: 44927 | JC1: 44933 | JD1: 44938 | JE1: 44945 | JF1: 44953 | JG1: 44954 | JH1: 44961 | JI1: 44966 | JJ1: 44968 | JK1: 44989 | JL1: 44990 | JM1: 44996 | JN1: 44999 | JO1: 45001 | JP1: 45003 | JQ1: 45008 | JR1: 45008 | JS1: 45010 | JT1: 45016 | JU1: 45022 | JV1: 45025 | JW1: 45027 | JX1: 45029 | JY1: 45031 | JZ1: 45031 | KA1: 45041 | KB1: 45043 | KC1: 45045 | KD1: 45051 | KE1: 45055 | KF1: 45057 | KG1: 45058 | KH1: 45059 | KI1: 45064 | KJ1: 45066 | KK1: 45067 | KL1: 45071 | KM1: 45073 | KN1: 45074 | KO1: 45079 | KP1: 45081 | KQ1: 45085 | KR1: 45087 | KS1: 45089 | KT1: 45092 | KU1: 45094 | KV1: 45097 | KW1: 45099 | KX1: 45106 | KY1: 45107 | KZ1: 45109 | LA1: 45110 | LB1: 45111 | LC1: 45113 | LD1: 45116 | LE1: 45121 | LF1: 45122 | LG1: 45126 | LH1: 45129 | LI1: 45134 | LJ1: 45143 | LK1: 45147 | LL1: 45148 | LM1: 45150 | LN1: 45155 | LO1: 45156 | LP1: 45158 | LQ1: 45162 | LR1: 45167 | LS1: 45170 | LT1: 45172 | LU1: 45178 | LV1: 45181 | LW1: 45184 | LX1: 45185 | LY1: 45187 | LZ1: 45190 | MA1: 45191 | MB1: 45192 | MC1: 45193 | MD1: 45194 | ME1: 45197 | MF1: 45199 | MG1: 45202 | MH1: 45206 | MI1: 45212 | MJ1: 45218 | MK1: 45225 | ML1: 45227 | MM1: 45232 | MN1: 45237 | MO1: 45240 | MP1: 45242 | MQ1: 45243 | MR1: 45245 | MS1: 45246 | MT1: 45247 | MU1: 45248 | MV1: 45249 | MW1: 45252 | MX1: 45254 | MY1: 45255 | MZ1: 45256 | NA1: 45259 | NB1: 45262 | NC1: 45272 | ND1: 45274 | NE1: 45278 | NF1: 45281 | NG1: 45287 | NH1: 45291 | NI1: 45302 | NJ1: 45309 | NK1: 45311 | NL1: 45317 | NM1: 45318 | NN1: 45319 | NO1: 45323 | NP1: 45325 | NQ1: 45330 | NR1: 45332 | NS1: 45337 | NT1: 45339 | NU1: 45344 | NV1: 45650 | NW1: 45351 | NX1: 45353 | NY1: 45358 | NZ1: 45360 | OA1: 45364 | OB1: 45367 | OC1: 45372 | OD1: 45380 | OE1: 45381 | OF1: 45392 | OG1: 45393 | OH1: 45395 | OI1: 45397 | OJ1: 45398 | OK1: 45391 | OL1: 45407 | OM1: 45416 | ON1: 45424 | OO1: 45426 | OP1: 45430 | OQ1: 45438 | OR1: 45444 | OS1: 45451 | OT1: 45458 | OU1: 45465 | OV1: 45471 | OW1: 45472 | OX1: 45476 | OY1: 45481 | OZ1: 45485 | PA1: 45486 | PB1: 45493 | PC1: 45494 | PD1: 45497 | PE1: 45498 | PF1: 45516 | PG1: 45521 | PH1: 45534 | PI1: 45536 | PJ1: 45598 | PK1: 45611 | PL1: 45619 | PM1: 45624 | PN1: 45633 | PO1: 45637 | PP1: 45641 | PQ1: 45654 | PR1: 45655 | PS1: 45657 | PT1: 45661 | PU1: 45664 | PV1: 45666 | PW1: 45668 | PX1: 45675 | PY1: 45683 | PZ1: 45690 | QA1: 45696 | QB1: 45699 | QC1: 45704 | QD1: 45711 | QE1: 45719 | QF1: 45723 | QG1: 45731 | QH1: 45743 | QI1: 45745 | QJ1: 45752 | QK1: 45754 | QL1: 45757 | QM1: 45758 | QN1: 45759 | QO1: 45764 | QP1: 45772 | QQ1: 45773 | QR1: 45774 | QS1: 45775 | QT1: 45785 | QU1: 45788 | QV1: 45794 | QW1: 45799 | QX1: 45801 | QY1: 45807 | QZ1: 45808 | RA1: 45815 | RB1: 45821 | RC1: 45823 | RD1: 45829 | RE1: 45830 | RF1: 45836 | RG1: 45837 | RH1: 45838 | RI1: 45841 | RJ1: 45842 | RK1: 45844 | RL1: 45845 | RM1: 45853 | RN1: 45875 | RO1: 45879 | RP1: 45881 | RQ1: 45885 | RR1: 45886 | RS1: 45889 | RT1: 45892 | RU1: 45897 | RV1: 45898 | RW1: 45899 | RX1: 45900 | RY1: 45903 | RZ1: 45906 | SA1: 45914 | SB1: 45917 | SC1: 45922 | SD1: 45924 | SE1: 45930 | SF1: 45931 | SG1: 45934 | SH1: 45941 | SI1: 45948 | SJ1: 45961 | SK1: 45966 | SL1: 45968 | SM1: 45969 | SN1: 45970 | SO1: 45976 | SP1: 45983 | SQ1: 45983 | SR1: 45990 | SS1: 45991 | ST1: 45994 | SU1: 45997 | SV1: 46016 | SW1: 46017 | SX1: 46023 | SY1: 46025 | SZ1: 46032 | TA1: 46039 | TB1: 46041 | TC1: 46044 | TD1: 46050 | TE1: 46067 | TF1: 46074 | TG1: 46081 | TH1: 46084 | TI1: 46085 | TJ1: 46089 | TK1: 46091 | TL1: 46109 | TM1: 46121 | TN1: 46137 | TO1: 46156 | TP1: 46159 | TQ1: 46160 | TR1: 46167 | TS1: 46186
