Workbook

Sheet Raw Games
A1: Date | B1: Where | C1: Half | D1: aa | E1: Aurora | F1: Lucas | G1: Lily | H1: Owen | I1: Cooper | J1: Lucy | K1: Luna | L1: Layla | N1: Min | O1: Max | P1: Winner | Q1: Loser | R1: Players
A2: 43134 | B2: Preston | E2: 690 | F2: 765 | G2: 520 | J2: 695 | L2: 700 | N2: =MIN($D2:$M2) -> 520 | O2: =MAX($D2:$M2) -> 765 | P2: Debby | Q2: David | R2: =COUNT(D2:M2) -> 5
A3: 43135 | B3: Preston | E3: 385 | F3: 510 | H3: 300 | J3: 365 | N3: =MIN($D3:$M3) -> 300 | O3: =MAX($D3:$M3) -> 510 | P3: Jeff M | Q3: David | R3: =COUNT(D3:M3) -> 4
A4: 43136 | B4: Preston | E4: 495 | F4: 195 | G4: 795 | J4: 450 | N4: =MIN($D4:$M4) -> 195 | O4: =MAX($D4:$M4) -> 795 | P4: David | Q4: Debby | R4: =COUNT(D4:M4) -> 4
A5: 43137 | B5: Preston | F5: 65 | G5: 485 | I5: 895 | J5: 540 | N5: =MIN($D5:$M5) -> 65 | O5: =MAX($D5:$M5) -> 895 | P5: David | Q5: Nancy | R5: =COUNT(D5:M5) -> 4
A6: 43138 | B6: Preston | E6: 280 | F6: 535 | G6: 525 | J6: 900 | N6: =MIN($D6:$M6) -> 280 | O6: =MAX($D6:$M6) -> 900 | P6: Charlene | Q6: Nancy | R6: =COUNT(D6:M6) -> 4
A7: =A6+2 -> 43140 | B7: Preston | E7: 460 | F7: 225 | G7: 395 | J7: 675 | N7: =MIN($D7:$M7) -> 225 | O7: =MAX($D7:$M7) -> 675 | P7: David | Q7: Nancy | R7: =COUNT(D7:M7) -> 4
A8: =A7+2 -> 43142 | B8: Preston | E8: 190 | F8: 450 | H8: 305 | J8: 550 | N8: =MIN($D8:$M8) -> 190 | O8: =MAX($D8:$M8) -> 550 | P8: Charlene | Q8: Nancy | R8: =COUNT(D8:M8) -> 4
A9: =A8+2 -> 43144 | B9: Preston | E9: 400 | G9: 235 | J9: 260 | K9: 240 | N9: =MIN($D9:$M9) -> 235 | O9: =MAX($D9:$M9) -> 400 | P9: Debby | Q9: Charlene | R9: =COUNT(D9:M9) -> 4
A10: =A9+2 -> 43146 | B10: Preston | E10: 165 | F10: 400 | G10: 250 | J10: 190 | N10: =MIN($D10:$M10) -> 165 | O10: =MAX($D10:$M10) -> 400 | P10: Charlene | Q10: David | R10: =COUNT(D10:M10) -> 4
A11: =A10+2 -> 43148 | B11: Preston | E11: 445 | G11: 370 | H11: 465 | J11: 430 | N11: =MIN($D11:$M11) -> 370 | O11: =MAX($D11:$M11) -> 465 | P11: Debby | Q11: Jeff M | R11: =COUNT(D11:M11) -> 4
A12: =A11+2 -> 43150 | B12: Preston | E12: 525 | F12: 330 | G12: 540 | J12: 675 | N12: =MIN($D12:$M12) -> 330 | O12: =MAX($D12:$M12) -> 675 | P12: David | Q12: Nancy | R12: =COUNT(D12:M12) -> 4
A13: =A12+2 -> 43152 | B13: Preston | E13: 405 | F13: 385 | G13: 630 | J13: 410 | K13: 380 | N13: =MIN($D13:$M13) -> 380 | O13: =MAX($D13:$M13) -> 630 | P13: Sally | Q13: Debby | R13: =COUNT(D13:M13) -> 5
A14: =A13+2 -> 43154 | B14: Preston | E14: 250 | F14: 690 | J14: 515 | K14: 800 | N14: =MIN($D14:$M14) -> 250 | O14: =MAX($D14:$M14) -> 800 | P14: Charlene | Q14: Sally | R14: =COUNT(D14:M14) -> 4
A15: =A14+2 -> 43156 | B15: Preston | C15: Yes | E15: 95 | F15: 240 | H15: 95 | J15: 265 | N15: =MIN($D15:$M15) -> 95 | O15: =MAX($D15:$M15) -> 265 | P15: Charlene | Q15: Nancy | R15: =COUNT(D15:M15) -> 4
A16: =A15+2 -> 43158 | B16: Preston | E16: 455 | F16: 630 | G16: 395 | J16: 380 | K16: 650 | N16: =MIN($D16:$M16) -> 380 | O16: =MAX($D16:$M16) -> 650 | P16: Nancy | Q16: Sally | R16: =COUNT(D16:M16) -> 5
A17: =A16+2 -> 43160 | B17: Preston | C17: Yes | F17: 465 | G17: 405 | J17: 75 | L17: 420 | N17: =MIN($D17:$M17) -> 75 | O17: =MAX($D17:$M17) -> 465 | P17: Nancy | Q17: David | R17: =COUNT(D17:M17) -> 4
A18: =A17+2 -> 43162 | B18: Preston | E18: 260 | F18: 285 | G18: 570 | J18: 695 | L18: 780 | N18: =MIN($D18:$M18) -> 260 | O18: =MAX($D18:$M18) -> 780 | P18: Charlene | Q18: Sandy | R18: =COUNT(D18:M18) -> 5
A19: =A18+2 -> 43164 | B19: Superior | E19: 575 | F19: 510 | H19: 565 | K19: 400 | N19: =MIN($D19:$M19) -> 400 | O19: =MAX($D19:$M19) -> 575 | P19: Sally | Q19: Charlene | R19: =COUNT(D19:M19) -> 4
A20: 43289 | B20: Superior | E20: 95 | F20: 705 | H20: 775 | J20: 400 | N20: =MIN($D20:$M20) -> 95 | O20: =MAX($D20:$M20) -> 775 | P20: Charlene | Q20: Jeff M | R20: =COUNT(D20:M20) -> 4
A21: =A20+2 -> 43291 | B21: Preston | C21: Yes | E21: 155 | F21: 100 | G21: 495 | H21: 240 | J21: 235 | N21: =MIN($D21:$M21) -> 100 | O21: =MAX($D21:$M21) -> 495 | P21: David | Q21: Debby | R21: =COUNT(D21:M21) -> 5
A22: =A21+2 -> 43293 | B22: Preston | C22: Yes | E22: 235 | F22: 135 | G22: 375 | J22: 145 | K22: 120 | N22: =MIN($D22:$M22) -> 120 | O22: =MAX($D22:$M22) -> 375 | P22: Sally | Q22: Debby | R22: =COUNT(D22:M22) -> 5
A23: =A22+2 -> 43295 | B23: Preston | G23: 155 | H23: 655 | J23: 245 | N23: =MIN($D23:$M23) -> 155 | O23: =MAX($D23:$M23) -> 655 | P23: Debby | Q23: Jeff M | R23: =COUNT(D23:M23) -> 3
A24: =A23+2 -> 43297 | B24: Preston | C24: Yes | F24: 160 | G24: 335 | I24: 320 | J24: 145 | N24: =MIN($D24:$M24) -> 145 | O24: =MAX($D24:$M24) -> 335 | P24: Nancy | Q24: Debby | R24: =COUNT(D24:M24) -> 4
A25: =A24+2 -> 43299 | B25: Preston | E25: 125 | F25: 655 | G25: 720 | J25: 390 | N25: =MIN($D25:$M25) -> 125 | O25: =MAX($D25:$M25) -> 720 | P25: Charlene | Q25: Debby | R25: =COUNT(D25:M25) -> 4
A26: =A25+2 -> 43301 | B26: Superior | E26: 175 | F26: 625 | G26: 285 | J26: 185 | N26: =MIN($D26:$M26) -> 175 | O26: =MAX($D26:$M26) -> 625 | P26: Charlene | Q26: David | R26: =COUNT(D26:M26) -> 4
A27: =A26+2 -> 43303 | B27: Preston | E27: 595 | F27: 455 | G27: 585 | J27: 520 | N27: =MIN($D27:$M27) -> 455 | O27: =MAX($D27:$M27) -> 595 | P27: David | Q27: Charlene | R27: =COUNT(D27:M27) -> 4
A28: =A27+2 -> 43305 | B28: Superior | E28: 535 | F28: 590 | G28: 635 | H28: 905 | J28: 480 | N28: =MIN($D28:$M28) -> 480 | O28: =MAX($D28:$M28) -> 905 | P28: Nancy | Q28: Jeff M | R28: =COUNT(D28:M28) -> 5
A29: =A28+2 -> 43307 | B29: Superior | E29: 840 | F29: 725 | G29: 950 | J29: 150 | L29: 565 | N29: =MIN($D29:$M29) -> 150 | O29: =MAX($D29:$M29) -> 950 | P29: Nancy | Q29: Debby | R29: =COUNT(D29:M29) -> 5
A30: =A29+2 -> 43309 | B30: Preston | E30: 635 | F30: 665 | G30: 500 | J30: 520 | N30: =MIN($D30:$M30) -> 500 | O30: =MAX($D30:$M30) -> 665 | P30: Debby | Q30: David | R30: =COUNT(D30:M30) -> 4
A31: =A30+2 -> 43311 | B31: Preston | C31: Yes | E31: 235 | F31: 265 | G31: 270 | H31: 110 | J31: 360 | N31: =MIN($D31:$M31) -> 110 | O31: =MAX($D31:$M31) -> 360 | P31: Jeff M | Q31: Nancy | R31: =COUNT(D31:M31) -> 5
A32: =A31+2 -> 43313 | B32: Preston | F32: 665 | I32: 705 | J32: 285 | K32: 605 | N32: =MIN($D32:$M32) -> 285 | O32: =MAX($D32:$M32) -> 705 | P32: Nancy | Q32: Karen | R32: =COUNT(D32:M32) -> 4
A33: =A32+2 -> 43315 | B33: Superior | E33: 125 | F33: 240 | J33: 520 | L33: 495 | N33: =MIN($D33:$M33) -> 125 | O33: =MAX($D33:$M33) -> 520 | P33: Charlene | Q33: Nancy | R33: =COUNT(D33:M33) -> 4
A34: =A33+2 -> 43317 | B34: Superior | E34: 485 | F34: 180 | G34: 330 | J34: 460 | N34: =MIN($D34:$M34) -> 180 | O34: =MAX($D34:$M34) -> 485 | P34: David | Q34: Charlene | R34: =COUNT(D34:M34) -> 4
A35: =A34+2 -> 43319 | B35: Superior | E35: 330 | F35: 480 | G35: 270 | J35: 470 | N35: =MIN($D35:$M35) -> 270 | O35: =MAX($D35:$M35) -> 480 | P35: Debby | Q35: David | R35: =COUNT(D35:M35) -> 4
A36: =A35+2 -> 43321 | B36: Preston | E36: 100 | F36: 485 | J36: 550 | L36: 800 | N36: =MIN($D36:$M36) -> 100 | O36: =MAX($D36:$M36) -> 800 | P36: Charlene | Q36: Sandy | R36: =COUNT(D36:M36) -> 4
A37: =A36+2 -> 43323 | B37: Preston | F37: 325 | G37: 330 | J37: 460 | K37: 250 | N37: =MIN($D37:$M37) -> 250 | O37: =MAX($D37:$M37) -> 460 | P37: Sally | Q37: Nancy | R37: =COUNT(D37:M37) -> 4
A38: =A37+2 -> 43325 | B38: Preston | C38: Yes | E38: 165 | F38: 105 | G38: 455 | J38: 250 | N38: =MIN($D38:$M38) -> 105 | O38: =MAX($D38:$M38) -> 455 | P38: David | Q38: Debby | R38: =COUNT(D38:M38) -> 4
A39: =A38+2 -> 43327 | B39: Preston | F39: 390 | G39: 315 | J39: 325 | L39: 710 | N39: =MIN($D39:$M39) -> 315 | O39: =MAX($D39:$M39) -> 710 | P39: Debby | Q39: Sandy | R39: =COUNT(D39:M39) -> 4
A40: 43415 | B40: Superior | E40: 560 | F40: 305 | J40: 195 | L40: 315 | N40: =MIN($D40:$M40) -> 195 | O40: =MAX($D40:$M40) -> 560 | P40: Nancy | Q40: Charlene | R40: =COUNT(D40:M40) -> 4
...

Sheet Leaders (dont edit)
A1: {=INDEX('Stats (dont edit)'!1:1,0)} -> Name | B1: Games | C1: Wins | D1: Win % | E1: Losses | F1: Loss % | G1: Lowest | H1: Highest | I1: Avg | J1: All Time | K1: Rank | L1: Score | M1: 0 | N1: 0 | O1: 0 | P1: 0 | Q1: 0 | R1: 0 | S1: 0 | T1: 0 | U1: 0 | V1: 0 | W1: 0 | X1: 0 | Y1: 0 | Z1: 0 | AA1: 0 | AB1: 0 | AC1: 0 | AD1: 0 | AE1: 0 | AF1: 0
A2: =IFERROR(__xludf.DUMMYFUNCTION("SORT(FILTER('Stats (dont edit)'!A2:L1000,'Stats (dont edit)'!D2:D1000<>""""),11,TRUE)"),"Karenina") -> Karenina | B2: =IFERROR(__xludf.DUMMYFUNCTION("""COMPUTED_VALUE"""),18) -> 18 | C2: =IFERROR(__xludf.DUMMYFUNCTION("""COMPUTED_VALUE"""),6) -> 6 | D2: =IFERROR(__xludf.DUMMYFUNCTION("""COMPUTED_VALUE"""),0.333333333333333) -> 0.33333333 | E2: =IFERROR(__xludf.DUMMYFUNCTION("""COMPUTED_VALUE"""),2) -> 2 | F2: =IFERROR(__xludf.DUMMYFUNCTION("""COMPUTED_VALUE"""),0.111111111111111) -> 0.11111111 | G2: =IFERROR(__xludf.DUMMYFUNCTION("""COMPUTED_VALUE"""),60) -> 60 | H2: =IFERROR(__xludf.DUMMYFUNCTION("""COMPUTED_VALUE"""),800) -> 800 | I2: =IFERROR(__xludf.DUMMYFUNCTION("""COMPUTED_VALUE"""),359.444444444444) -> 359.44444 | J2: =IFERROR(__xludf.DUMMYFUNCTION("""COMPUTED_VALUE"""),6470) -> 6470 | K2: =IFERROR(__xludf.DUMMYFUNCTION("""COMPUTED_VALUE"""),1) -> 1 | L2: =IFERROR(__xludf.DUMMYFUNCTION("""COMPUTED_VALUE"""),1.58333333333333) -> 1.5833333
A3: =IFERROR(__xludf.DUMMYFUNCTION("""COMPUTED_VALUE"""),"Jeff M") -> Jeff M | B3: =IFERROR(__xludf.DUMMYFUNCTION("""COMPUTED_VALUE"""),81) -> 81 | C3: =IFERROR(__xludf.DUMMYFUNCTION("""COMPUTED_VALUE"""),23) -> 23 | D3: =IFERROR(__xludf.DUMMYFUNCTION("""COMPUTED_VALUE"""),0.28395061728395) -> 0.28395062 | E3: =IFERROR(__xludf.DUMMYFUNCTION("""COMPUTED_VALUE"""),26) -> 26 | F3: =IFERROR(__xludf.DUMMYFUNCTION("""COMPUTED_VALUE"""),0.320987654320987) -> 0.32098765 | G3: =IFERROR(__xludf.DUMMYFUNCTION("""COMPUTED_VALUE"""),15) -> 15 | H3: =IFERROR(__xludf.DUMMYFUNCTION("""COMPUTED_VALUE"""),1310) -> 1310 | I3: =IFERROR(__xludf.DUMMYFUNCTION("""COMPUTED_VALUE"""),428.456790123456) -> 428.45679 | J3: =IFERROR(__xludf.DUMMYFUNCTION("""COMPUTED_VALUE"""),34705) -> 34705 | K3: =IFERROR(__xludf.DUMMYFUNCTION("""COMPUTED_VALUE"""),2) -> 2 | L3: =IFERROR(__xludf.DUMMYFUNCTION("""COMPUTED_VALUE"""),1.15668343240359) -> 1.1566834
A4: =IFERROR(__xludf.DUMMYFUNCTION("""COMPUTED_VALUE"""),"David") -> David | B4: =IFERROR(__xludf.DUMMYFUNCTION("""COMPUTED_VALUE"""),493) -> 493 | C4: =IFERROR(__xludf.DUMMYFUNCTION("""COMPUTED_VALUE"""),148) -> 148 | D4: =IFERROR(__xludf.DUMMYFUNCTION("""COMPUTED_VALUE"""),0.300202839756592) -> 0.30020284 | E4: =IFERROR(__xludf.DUMMYFUNCTION("""COMPUTED_VALUE"""),98) -> 98 | F4: =IFERROR(__xludf.DUMMYFUNCTION("""COMPUTED_VALUE"""),0.198782961460446) -> 0.19878296 | G4: =IFERROR(__xludf.DUMMYFUNCTION("""COMPUTED_VALUE"""),5) -> 5 | H4: =IFERROR(__xludf.DUMMYFUNCTION("""COMPUTED_VALUE"""),1080) -> 1080 | I4: =IFERROR(__xludf.DUMMYFUNCTION("""COMPUTED_VALUE"""),396.876267748478) -> 396.87627 | J4: =IFERROR(__xludf.DUMMYFUNCTION("""COMPUTED_VALUE"""),195660) -> 195660 | K4: =IFERROR(__xludf.DUMMYFUNCTION("""COMPUTED_VALUE"""),3) -> 3 | L4: =IFERROR(__xludf.DUMMYFUNCTION("""COMPUTED_VALUE"""),1.13838773251484) -> 1.1383877
A5: =IFERROR(__xludf.DUMMYFUNCTION("""COMPUTED_VALUE"""),"Karen") -> Karen | B5: =IFERROR(__xludf.DUMMYFUNCTION("""COMPUTED_VALUE"""),34) -> 34 | C5: =IFERROR(__xludf.DUMMYFUNCTION("""COMPUTED_VALUE"""),9) -> 9 | D5: =IFERROR(__xludf.DUMMYFUNCTION("""COMPUTED_VALUE"""),0.264705882352941) -> 0.26470588 | E5: =IFERROR(__xludf.DUMMYFUNCTION("""COMPUTED_VALUE"""),12) -> 12 | F5: =IFERROR(__xludf.DUMMYFUNCTION("""COMPUTED_VALUE"""),0.352941176470588) -> 0.35294118 | G5: =IFERROR(__xludf.DUMMYFUNCTION("""COMPUTED_VALUE"""),55) -> 55 | H5: =IFERROR(__xludf.DUMMYFUNCTION("""COMPUTED_VALUE"""),890) -> 890 | I5: =IFERROR(__xludf.DUMMYFUNCTION("""COMPUTED_VALUE"""),430.147058823529) -> 430.14706 | J5: =IFERROR(__xludf.DUMMYFUNCTION("""COMPUTED_VALUE"""),14625) -> 14625 | K5: =IFERROR(__xludf.DUMMYFUNCTION("""COMPUTED_VALUE"""),4) -> 4 | L5: =IFERROR(__xludf.DUMMYFUNCTION("""COMPUTED_VALUE"""),1.1038062283737) -> 1.1038062
A6: =IFERROR(__xludf.DUMMYFUNCTION("""COMPUTED_VALUE"""),"Charlene") -> Charlene | B6: =IFERROR(__xludf.DUMMYFUNCTION("""COMPUTED_VALUE"""),342) -> 342 | C6: =IFERROR(__xludf.DUMMYFUNCTION("""COMPUTED_VALUE"""),89) -> 89 | D6: =IFERROR(__xludf.DUMMYFUNCTION("""COMPUTED_VALUE"""),0.260233918128655) -> 0.26023392 | E6: =IFERROR(__xludf.DUMMYFUNCTION("""COMPUTED_VALUE"""),75) -> 75 | F6: =IFERROR(__xludf.DUMMYFUNCTION("""COMPUTED_VALUE"""),0.219298245614035) -> 0.21929825 | G6: =IFERROR(__xludf.DUMMYFUNCTION("""COMPUTED_VALUE"""),45) -> 45 | H6: =IFERROR(__xludf.DUMMYFUNCTION("""COMPUTED_VALUE"""),1020) -> 1020 | I6: =IFERROR(__xludf.DUMMYFUNCTION("""COMPUTED_VALUE"""),416.959064327485) -> 416.95906 | J6: =IFERROR(__xludf.DUMMYFUNCTION("""COMPUTED_VALUE"""),142600) -> 142600 | K6: =IFERROR(__xludf.DUMMYFUNCTION("""COMPUTED_VALUE"""),5) -> 5 | L6: =IFERROR(__xludf.DUMMYFUNCTION("""COMPUTED_VALUE"""),1.07345850005129) -> 1.0734585
A7: =IFERROR(__xludf.DUMMYFUNCTION("""COMPUTED_VALUE"""),"Nancy") -> Nancy | B7: =IFERROR(__xludf.DUMMYFUNCTION("""COMPUTED_VALUE"""),514) -> 514 | C7: =IFERROR(__xludf.DUMMYFUNCTION("""COMPUTED_VALUE"""),137) -> 137 | D7: =IFERROR(__xludf.DUMMYFUNCTION("""COMPUTED_VALUE"""),0.266536964980544) -> 0.26653696 | E7: =IFERROR(__xludf.DUMMYFUNCTION("""COMPUTED_VALUE"""),114) -> 114 | F7: =IFERROR(__xludf.DUMMYFUNCTION("""COMPUTED_VALUE"""),0.221789883268482) -> 0.22178988 | G7: =IFERROR(__xludf.DUMMYFUNCTION("""COMPUTED_VALUE"""),30) -> 30 | H7: =IFERROR(__xludf.DUMMYFUNCTION("""COMPUTED_VALUE"""),1100) -> 1100 | I7: =IFERROR(__xludf.DUMMYFUNCTION("""COMPUTED_VALUE"""),406.038910505836) -> 406.03891 | J7: =IFERROR(__xludf.DUMMYFUNCTION("""COMPUTED_VALUE"""),208704) -> 208704 | K7: =IFERROR(__xludf.DUMMYFUNCTION("""COMPUTED_VALUE"""),6) -> 6 | L7: =IFERROR(__xludf.DUMMYFUNCTION("""COMPUTED_VALUE"""),1.02755529985313) -> 1.0275553
A8: =IFERROR(__xludf.DUMMYFUNCTION("""COMPUTED_VALUE"""),"Debby") -> Debby | B8: =IFERROR(__xludf.DUMMYFUNCTION("""COMPUTED_VALUE"""),184) -> 184 | C8: =IFERROR(__xludf.DUMMYFUNCTION("""COMPUTED_VALUE"""),43) -> 43 | D8: =IFERROR(__xludf.DUMMYFUNCTION("""COMPUTED_VALUE"""),0.233695652173913) -> 0.23369565 | E8: =IFERROR(__xludf.DUMMYFUNCTION("""COMPUTED_VALUE"""),55) -> 55 | F8: =IFERROR(__xludf.DUMMYFUNCTION("""COMPUTED_VALUE"""),0.29891304347826) -> 0.29891304 | G8: =IFERROR(__xludf.DUMMYFUNCTION("""COMPUTED_VALUE"""),25) -> 25 | H8: =IFERROR(__xludf.DUMMYFUNCTION("""COMPUTED_VALUE"""),1025) -> 1025 | I8: =IFERROR(__xludf.DUMMYFUNCTION("""COMPUTED_VALUE"""),459.130434782608) -> 459.13043 | J8: =IFERROR(__xludf.DUMMYFUNCTION("""COMPUTED_VALUE"""),84480) -> 84480 | K8: =IFERROR(__xludf.DUMMYFUNCTION("""COMPUTED_VALUE"""),7) -> 7 | L8: =IFERROR(__xludf.DUMMYFUNCTION("""COMPUTED_VALUE"""),0.977108931947069) -> 0.97710893
A9: =IFERROR(__xludf.DUMMYFUNCTION("""COMPUTED_VALUE"""),"Sally") -> Sally | B9: =IFERROR(__xludf.DUMMYFUNCTION("""COMPUTED_VALUE"""),207) -> 207 | C9: =IFERROR(__xludf.DUMMYFUNCTION("""COMPUTED_VALUE"""),45) -> 45 | D9: =IFERROR(__xludf.DUMMYFUNCTION("""COMPUTED_VALUE"""),0.217391304347826) -> 0.2173913 | E9: =IFERROR(__xludf.DUMMYFUNCTION("""COMPUTED_VALUE"""),78) -> 78 | F9: =IFERROR(__xludf.DUMMYFUNCTION("""COMPUTED_VALUE"""),0.376811594202898) -> 0.37681159 | G9: =IFERROR(__xludf.DUMMYFUNCTION("""COMPUTED_VALUE"""),40) -> 40 | H9: =IFERROR(__xludf.DUMMYFUNCTION("""COMPUTED_VALUE"""),1185) -> 1185 | I9: =IFERROR(__xludf.DUMMYFUNCTION("""COMPUTED_VALUE"""),446.71497584541) -> 446.71498 | J9: =IFERROR(__xludf.DUMMYFUNCTION("""COMPUTED_VALUE"""),92470) -> 92470 | K9: =IFERROR(__xludf.DUMMYFUNCTION("""COMPUTED_VALUE"""),8) -> 8 | L9: =IFERROR(__xludf.DUMMYFUNCTION("""COMPUTED_VALUE"""),0.766108894023197) -> 0.76610889
A10: =IFERROR(__xludf.DUMMYFUNCTION("""COMPUTED_VALUE"""),"Sara") -> Sara | B10: =IFERROR(__xludf.DUMMYFUNCTION("""COMPUTED_VALUE"""),26) -> 26 | C10: =IFERROR(__xludf.DUMMYFUNCTION("""COMPUTED_VALUE"""),5) -> 5 | D10: =IFERROR(__xludf.DUMMYFUNCTION("""COMPUTED_VALUE"""),0.192307692307692) -> 0.19230769 | E10: =IFERROR(__xludf.DUMMYFUNCTION("""COMPUTED_VALUE"""),7) -> 7 | F10: =IFERROR(__xludf.DUMMYFUNCTION("""COMPUTED_VALUE"""),0.269230769230769) -> 0.26923077 | G10: =IFERROR(__xludf.DUMMYFUNCTION("""COMPUTED_VALUE"""),45) -> 45 | H10: =IFERROR(__xludf.DUMMYFUNCTION("""COMPUTED_VALUE"""),940) -> 940 | I10: =IFERROR(__xludf.DUMMYFUNCTION("""COMPUTED_VALUE"""),367.692307692307) -> 367.69231 | J10: =IFERROR(__xludf.DUMMYFUNCTION("""COMPUTED_VALUE"""),9560) -> 9560 | K10: =IFERROR(__xludf.DUMMYFUNCTION("""COMPUTED_VALUE"""),9) -> 9 | L10: =IFERROR(__xludf.DUMMYFUNCTION("""COMPUTED_VALUE"""),0.692307692307692) -> 0.69230769
A11: =IFERROR(__xludf.DUMMYFUNCTION("""COMPUTED_VALUE"""),"Sandy") -> Sandy | B11: =IFERROR(__xludf.DUMMYFUNCTION("""COMPUTED_VALUE"""),138) -> 138 | C11: =IFERROR(__xludf.DUMMYFUNCTION("""COMPUTED_VALUE"""),21) -> 21 | D11: =IFERROR(__xludf.DUMMYFUNCTION("""COMPUTED_VALUE"""),0.152173913043478) -> 0.15217391 | E11: =IFERROR(__xludf.DUMMYFUNCTION("""COMPUTED_VALUE"""),43) -> 43 | F11: =IFERROR(__xludf.DUMMYFUNCTION("""COMPUTED_VALUE"""),0.31159420289855) -> 0.3115942 | G11: =IFERROR(__xludf.DUMMYFUNCTION("""COMPUTED_VALUE"""),40) -> 40 | H11: =IFERROR(__xludf.DUMMYFUNCTION("""COMPUTED_VALUE"""),1120) -> 1120 | I11: =IFERROR(__xludf.DUMMYFUNCTION("""COMPUTED_VALUE"""),501.884057971014) -> 501.88406 | J11: =IFERROR(__xludf.DUMMYFUNCTION("""COMPUTED_VALUE"""),69260) -> 69260 | K11: =IFERROR(__xludf.DUMMYFUNCTION("""COMPUTED_VALUE"""),10) -> 10 | L11: =IFERROR(__xludf.DUMMYFUNCTION("""COMPUTED_VALUE"""),0.657004830917874) -> 0.65700483

Sheet Stats (dont edit)
A1: Name | B1: Games | C1: Wins | D1: Win % | E1: Losses | F1: Loss % | G1: Lowest | H1: Highest | I1: Avg | J1: All Time | K1: Rank | L1: Score
A2: =('Pivot (dont edit)'!A4) -> aa | B2: =COUNT('Pivot (dont edit)'!4:4) -> 917 | C2: =COUNTIF('Raw Games'!P:P,$A2) -> 0 | D2: =IF($B2>'Constants (dont edit)'!$B$3,C2/$B2,"") -> 0 | E2: =COUNTIF('Raw Games'!Q:Q,$A2) -> 0 | F2: =IF($B2>'Constants (dont edit)'!$B$3,E2/$B2,"") -> 0 | G2: =MIN('Pivot (dont edit)'!4:4) -> #N/A | H2: =MAX('Pivot (dont edit)'!4:4) -> #N/A | I2: =IF(AND(B2>='Constants (dont edit)'!$B$4,SUM('Pivot (dont edit)'!4:4)>0), AVERAGE('Pivot (dont edit)'!4:4), "") -> #N/A | J2: =SUM('Pivot (dont edit)'!4:4) -> #N/A | K2: =RANK(L2,L:L) -> 1 | L2: =IF($B2>'Constants (dont edit)'!$B$3,(SUMIF('Raw Games'!P:P,$A2,'Raw Games'!R:R)-SUMIF('Raw Games'!Q:Q,$A2,'Raw Games'!R:R)/B2)/B2,0) -> 0
A3: =('Pivot (dont edit)'!A5) -> Aurora | B3: =COUNT('Pivot (dont edit)'!5:5) -> 917 | C3: =COUNTIF('Raw Games'!P:P,$A3) -> 0 | D3: =IF($B3>'Constants (dont edit)'!$B$3,C3/$B3,"") -> 0 | E3: =COUNTIF('Raw Games'!Q:Q,$A3) -> 0 | F3: =IF($B3>'Constants (dont edit)'!$B$3,E3/$B3,"") -> 0 | G3: =MIN('Pivot (dont edit)'!5:5) -> #N/A | H3: =MAX('Pivot (dont edit)'!5:5) -> #N/A | I3: =IF(AND(B3>='Constants (dont edit)'!$B$4,SUM('Pivot (dont edit)'!5:5)>0), AVERAGE('Pivot (dont edit)'!5:5), "") -> #N/A | J3: =SUM('Pivot (dont edit)'!5:5) -> #N/A | K3: =RANK(L3,L:L) -> 1 | L3: =IF($B3>'Constants (dont edit)'!$B$3,(SUMIF('Raw Games'!P:P,$A3,'Raw Games'!R:R)-SUMIF('Raw Games'!Q:Q,$A3,'Raw Games'!R:R)/B3)/B3,0) -> 0
A4: =('Pivot (dont edit)'!A6) -> Lucas | B4: =COUNT('Pivot (dont edit)'!6:6) -> 916 | C4: =COUNTIF('Raw Games'!P:P,$A4) -> 0 | D4: =IF($B4>'Constants (dont edit)'!$B$3,C4/$B4,"") -> 0 | E4: =COUNTIF('Raw Games'!Q:Q,$A4) -> 0 | F4: =IF($B4>'Constants (dont edit)'!$B$3,E4/$B4,"") -> 0 | G4: =MIN('Pivot (dont edit)'!6:6) -> #N/A | H4: =MAX('Pivot (dont edit)'!6:6) -> #N/A | I4: =IF(AND(B4>='Constants (dont edit)'!$B$4,SUM('Pivot (dont edit)'!6:6)>0), AVERAGE('Pivot (dont edit)'!6:6), "") -> #N/A | J4: =SUM('Pivot (dont edit)'!6:6) -> #N/A | K4: =RANK(L4,L:L) -> 1 | L4: =IF($B4>'Constants (dont edit)'!$B$3,(SUMIF('Raw Games'!P:P,$A4,'Raw Games'!R:R)-SUMIF('Raw Games'!Q:Q,$A4,'Raw Games'!R:R)/B4)/B4,0) -> 0
A5: =('Pivot (dont edit)'!A7) -> Lily | B5: =COUNT('Pivot (dont edit)'!7:7) -> 917 | C5: =COUNTIF('Raw Games'!P:P,$A5) -> 0 | D5: =IF($B5>'Constants (dont edit)'!$B$3,C5/$B5,"") -> 0 | E5: =COUNTIF('Raw Games'!Q:Q,$A5) -> 0 | F5: =IF($B5>'Constants (dont edit)'!$B$3,E5/$B5,"") -> 0 | G5: =MIN('Pivot (dont edit)'!7:7) -> #N/A | H5: =MAX('Pivot (dont edit)'!7:7) -> #N/A | I5: =IF(AND(B5>='Constants (dont edit)'!$B$4,SUM('Pivot (dont edit)'!7:7)>0), AVERAGE('Pivot (dont edit)'!7:7), "") -> #N/A | J5: =SUM('Pivot (dont edit)'!7:7) -> #N/A | K5: =RANK(L5,L:L) -> 1 | L5: =IF($B5>'Constants (dont edit)'!$B$3,(SUMIF('Raw Games'!P:P,$A5,'Raw Games'!R:R)-SUMIF('Raw Games'!Q:Q,$A5,'Raw Games'!R:R)/B5)/B5,0) -> 0
A6: =('Pivot (dont edit)'!A8) -> Owen | B6: =COUNT('Pivot (dont edit)'!8:8) -> 917 | C6: =COUNTIF('Raw Games'!P:P,$A6) -> 0 | D6: =IF($B6>'Constants (dont edit)'!$B$3,C6/$B6,"") -> 0 | E6: =COUNTIF('Raw Games'!Q:Q,$A6) -> 0 | F6: =IF($B6>'Constants (dont edit)'!$B$3,E6/$B6,"") -> 0 | G6: =MIN('Pivot (dont edit)'!8:8) -> #N/A | H6: =MAX('Pivot (dont edit)'!8:8) -> #N/A | I6: =IF(AND(B6>='Constants (dont edit)'!$B$4,SUM('Pivot (dont edit)'!8:8)>0), AVERAGE('Pivot (dont edit)'!8:8), "") -> #N/A | J6: =SUM('Pivot (dont edit)'!8:8) -> #N/A | K6: =RANK(L6,L:L) -> 1 | L6: =IF($B6>'Constants (dont edit)'!$B$3,(SUMIF('Raw Games'!P:P,$A6,'Raw Games'!R:R)-SUMIF('Raw Games'!Q:Q,$A6,'Raw Games'!R:R)/B6)/B6,0) -> 0
A7: =('Pivot (dont edit)'!A9) -> Cooper | B7: =COUNT('Pivot (dont edit)'!9:9) -> 917 | C7: =COUNTIF('Raw Games'!P:P,$A7) -> 0 | D7: =IF($B7>'Constants (dont edit)'!$B$3,C7/$B7,"") -> 0 | E7: =COUNTIF('Raw Games'!Q:Q,$A7) -> 0 | F7: =IF($B7>'Constants (dont edit)'!$B$3,E7/$B7,"") -> 0 | G7: =MIN('Pivot (dont edit)'!9:9) -> #N/A | H7: =MAX('Pivot (dont edit)'!9:9) -> #N/A | I7: =IF(AND(B7>='Constants (dont edit)'!$B$4,SUM('Pivot (dont edit)'!9:9)>0), AVERAGE('Pivot (dont edit)'!9:9), "") -> #N/A | J7: =SUM('Pivot (dont edit)'!9:9) -> #N/A | K7: =RANK(L7,L:L) -> 1 | L7: =IF($B7>'Constants (dont edit)'!$B$3,(SUMIF('Raw Games'!P:P,$A7,'Raw Games'!R:R)-SUMIF('Raw Games'!Q:Q,$A7,'Raw Games'!R:R)/B7)/B7,0) -> 0
A8: =('Pivot (dont edit)'!A10) -> Lucy | B8: =COUNT('Pivot (dont edit)'!10:10) -> 917 | C8: =COUNTIF('Raw Games'!P:P,$A8) -> 0 | D8: =IF($B8>'Constants (dont edit)'!$B$3,C8/$B8,"") -> 0 | E8: =COUNTIF('Raw Games'!Q:Q,$A8) -> 0 | F8: =IF($B8>'Constants (dont edit)'!$B$3,E8/$B8,"") -> 0 | G8: =MIN('Pivot (dont edit)'!10:10) -> #N/A | H8: =MAX('Pivot (dont edit)'!10:10) -> #N/A | I8: =IF(AND(B8>='Constants (dont edit)'!$B$4,SUM('Pivot (dont edit)'!10:10)>0), AVERAGE('Pivot (dont edit)'!10:10), "") -> #N/A | J8: =SUM('Pivot (dont edit)'!10:10) -> #N/A | K8: =RANK(L8,L:L) -> 1 | L8: =IF($B8>'Constants (dont edit)'!$B$3,(SUMIF('Raw Games'!P:P,$A8,'Raw Games'!R:R)-SUMIF('Raw Games'!Q:Q,$A8,'Raw Games'!R:R)/B8)/B8,0) -> 0
A9: =('Pivot (dont edit)'!A11) -> Luna | B9: =COUNT('Pivot (dont edit)'!11:11) -> 917 | C9: =COUNTIF('Raw Games'!P:P,$A9) -> 0 | D9: =IF($B9>'Constants (dont edit)'!$B$3,C9/$B9,"") -> 0 | E9: =COUNTIF('Raw Games'!Q:Q,$A9) -> 0 | F9: =IF($B9>'Constants (dont edit)'!$B$3,E9/$B9,"") -> 0 | G9: =MIN('Pivot (dont edit)'!11:11) -> #N/A | H9: =MAX('Pivot (dont edit)'!11:11) -> #N/A | I9: =IF(AND(B9>='Constants (dont edit)'!$B$4,SUM('Pivot (dont edit)'!11:11)>0), AVERAGE('Pivot (dont edit)'!11:11), "") -> #N/A | J9: =SUM('Pivot (dont edit)'!11:11) -> #N/A | K9: =RANK(L9,L:L) -> 1 | L9: =IF($B9>'Constants (dont edit)'!$B$3,(SUMIF('Raw Games'!P:P,$A9,'Raw Games'!R:R)-SUMIF('Raw Games'!Q:Q,$A9,'Raw Games'!R:R)/B9)/B9,0) -> 0
A10: =('Pivot (dont edit)'!A12) -> Layla | B10: =COUNT('Pivot (dont edit)'!12:12) -> 917 | C10: =COUNTIF('Raw Games'!P:P,$A10) -> 0 | D10: =IF($B10>'Constants (dont edit)'!$B$3,C10/$B10,"") -> 0 | E10: =COUNTIF('Raw Games'!Q:Q,$A10) -> 0 | F10: =IF($B10>'Constants (dont edit)'!$B$3,E10/$B10,"") -> 0 | G10: =MIN('Pivot (dont edit)'!12:12) -> #N/A | H10: =MAX('Pivot (dont edit)'!12:12) -> #N/A | I10: =IF(AND(B10>='Constants (dont edit)'!$B$4,SUM('Pivot (dont edit)'!12:12)>0), AVERAGE('Pivot (dont edit)'!12:12), "") -> #N/A | J10: =SUM('Pivot (dont edit)'!12:12) -> #N/A | K10: =RANK(L10,L:L) -> 1 | L10: =IF($B10>'Constants (dont edit)'!$B$3,(SUMIF('Raw Games'!P:P,$A10,'Raw Games'!R:R)-SUMIF('Raw Games'!Q:Q,$A10,'Raw Games'!R:R)/B10)/B10,0) -> 0
A11: =('Pivot (dont edit)'!A13) -> 0 | B11: =COUNT('Pivot (dont edit)'!13:13) -> 918 | C11: =COUNTIF('Raw Games'!P:P,$A11) -> 0 | D11: =IF($B11>'Constants (dont edit)'!$B$3,C11/$B11,"") -> 0 | E11: =COUNTIF('Raw Games'!Q:Q,$A11) -> 0 | F11: =IF($B11>'Constants (dont edit)'!$B$3,E11/$B11,"") -> 0 | G11: =MIN('Pivot (dont edit)'!13:13) -> #N/A | H11: =MAX('Pivot (dont edit)'!13:13) -> #N/A | I11: =IF(AND(B11>='Constants (dont edit)'!$B$4,SUM('Pivot (dont edit)'!13:13)>0), AVERAGE('Pivot (dont edit)'!13:13), "") -> #N/A | J11: =SUM('Pivot (dont edit)'!13:13) -> #N/A | K11: =RANK(L11,L:L) -> 1 | L11: =IF($B11>'Constants (dont edit)'!$B$3,(SUMIF('Raw Games'!P:P,$A11,'Raw Games'!R:R)-SUMIF('Raw Games'!Q:Q,$A11,'Raw Games'!R:R)/B11)/B11,0) -> 0
A12: =('Pivot (dont edit)'!A14) -> Min | B12: =COUNT('Pivot (dont edit)'!14:14) -> 917 | C12: =COUNTIF('Raw Games'!P:P,$A12) -> 0 | D12: =IF($B12>'Constants (dont edit)'!$B$3,C12/$B12,"") -> 0 | E12: =COUNTIF('Raw Games'!Q:Q,$A12) -> 0 | F12: =IF($B12>'Constants (dont edit)'!$B$3,E12/$B12,"") -> 0 | G12: =MIN('Pivot (dont edit)'!14:14) -> #N/A | H12: =MAX('Pivot (dont edit)'!14:14) -> #N/A | I12: =IF(AND(B12>='Constants (dont edit)'!$B$4,SUM('Pivot (dont edit)'!14:14)>0), AVERAGE('Pivot (dont edit)'!14:14), "") -> #N/A | J12: =SUM('Pivot (dont edit)'!14:14) -> #N/A | K12: =RANK(L12,L:L) -> 1 | L12: =IF($B12>'Constants (dont edit)'!$B$3,(SUMIF('Raw Games'!P:P,$A12,'Raw Games'!R:R)-SUMIF('Raw Games'!Q:Q,$A12,'Raw Games'!R:R)/B12)/B12,0) -> 0
A13: =('Pivot (dont edit)'!A15) -> Max | B13: =COUNT('Pivot (dont edit)'!15:15) -> 917 | C13: =COUNTIF('Raw Games'!P:P,$A13) -> 0 | D13: =IF($B13>'Constants (dont edit)'!$B$3,C13/$B13,"") -> 0 | E13: =COUNTIF('Raw Games'!Q:Q,$A13) -> 0 | F13: =IF($B13>'Constants (dont edit)'!$B$3,E13/$B13,"") -> 0 | G13: =MIN('Pivot (dont edit)'!15:15) -> #N/A | H13: =MAX('Pivot (dont edit)'!15:15) -> #N/A | I13: =IF(AND(B13>='Constants (dont edit)'!$B$4,SUM('Pivot (dont edit)'!15:15)>0), AVERAGE('Pivot (dont edit)'!15:15), "") -> #N/A | J13: =SUM('Pivot (dont edit)'!15:15) -> #N/A | K13: =RANK(L13,L:L) -> 1 | L13: =IF($B13>'Constants (dont edit)'!$B$3,(SUMIF('Raw Games'!P:P,$A13,'Raw Games'!R:R)-SUMIF('Raw Games'!Q:Q,$A13,'Raw Games'!R:R)/B13)/B13,0) -> 0
A14: =('Pivot (dont edit)'!A16) -> Winner | B14: =COUNT('Pivot (dont edit)'!16:16) -> 483 | C14: =COUNTIF('Raw Games'!P:P,$A14) -> 1 | D14: =IF($B14>'Constants (dont edit)'!$B$3,C14/$B14,"") -> 0.0020703934 | E14: =COUNTIF('Raw Games'!Q:Q,$A14) -> 0 | F14: =IF($B14>'Constants (dont edit)'!$B$3,E14/$B14,"") -> 0 | G14: =MIN('Pivot (dont edit)'!16:16) -> #N/A | H14: =MAX('Pivot (dont edit)'!16:16) -> #N/A | I14: =IF(AND(B14>='Constants (dont edit)'!$B$4,SUM('Pivot (dont edit)'!16:16)>0), AVERAGE('Pivot (dont edit)'!16:16), "") -> #N/A | J14: =SUM('Pivot (dont edit)'!16:16) -> #N/A | K14: =RANK(L14,L:L) -> 1 | L14: =IF($B14>'Constants (dont edit)'!$B$3,(SUMIF('Raw Games'!P:P,$A14,'Raw Games'!R:R)-SUMIF('Raw Games'!Q:Q,$A14,'Raw Games'!R:R)/B14)/B14,0) -> 0
A15: =('Pivot (dont edit)'!A17) -> Loser | B15: =COUNT('Pivot (dont edit)'!17:17) -> 483 | C15: =COUNTIF('Raw Games'!P:P,$A15) -> 0 | D15: =IF($B15>'Constants (dont edit)'!$B$3,C15/$B15,"") -> 0 | E15: =COUNTIF('Raw Games'!Q:Q,$A15) -> 1 | F15: =IF($B15>'Constants (dont edit)'!$B$3,E15/$B15,"") -> 0.0020703934 | G15: =MIN('Pivot (dont edit)'!17:17) -> #N/A | H15: =MAX('Pivot (dont edit)'!17:17) -> #N/A | I15: =IF(AND(B15>='Constants (dont edit)'!$B$4,SUM('Pivot (dont edit)'!17:17)>0), AVERAGE('Pivot (dont edit)'!17:17), "") -> #N/A | J15: =SUM('Pivot (dont edit)'!17:17) -> #N/A | K15: =RANK(L15,L:L) -> 1 | L15: =IF($B15>'Constants (dont edit)'!$B$3,(SUMIF('Raw Games'!P:P,$A15,'Raw Games'!R:R)-SUMIF('Raw Games'!Q:Q,$A15,'Raw Games'!R:R)/B15)/B15,0) -> 0
A16: =('Pivot (dont edit)'!A18) -> Players | B16: =COUNT('Pivot (dont edit)'!18:18) -> 917 | C16: =COUNTIF('Raw Games'!P:P,$A16) -> 0 | D16: =IF($B16>'Constants (dont edit)'!$B$3,C16/$B16,"") -> 0 | E16: =COUNTIF('Raw Games'!Q:Q,$A16) -> 0 | F16: =IF($B16>'Constants (dont edit)'!$B$3,E16/$B16,"") -> 0 | G16: =MIN('Pivot (dont edit)'!18:18) -> #N/A | H16: =MAX('Pivot (dont edit)'!18:18) -> #N/A | I16: =IF(AND(B16>='Constants (dont edit)'!$B$4,SUM('Pivot (dont edit)'!18:18)>0), AVERAGE('Pivot (dont edit)'!18:18), "") -> #N/A | J16: =SUM('Pivot (dont edit)'!18:18) -> #N/A | K16: =RANK(L16,L:L) -> 1 | L16: =IF($B16>'Constants (dont edit)'!$B$3,(SUMIF('Raw Games'!P:P,$A16,'Raw Games'!R:R)-SUMIF('Raw Games'!Q:Q,$A16,'Raw Games'!R:R)/B16)/B16,0) -> 0
A17: =('Pivot (dont edit)'!A19) -> 0 | B17: =COUNT('Pivot (dont edit)'!19:19) -> 918 | C17: =COUNTIF('Raw Games'!P:P,$A17) -> 0 | D17: =IF($B17>'Constants (dont edit)'!$B$3,C17/$B17,"") -> 0 | E17: =COUNTIF('Raw Games'!Q:Q,$A17) -> 0 | F17: =IF($B17>'Constants (dont edit)'!$B$3,E17/$B17,"") -> 0 | G17: =MIN('Pivot (dont edit)'!19:19) -> #N/A | H17: =MAX('Pivot (dont edit)'!19:19) -> #N/A | I17: =IF(AND(B17>='Constants (dont edit)'!$B$4,SUM('Pivot (dont edit)'!19:19)>0), AVERAGE('Pivot (dont edit)'!19:19), "") -> #N/A | J17: =SUM('Pivot (dont edit)'!19:19) -> #N/A | K17: =RANK(L17,L:L) -> 1 | L17: =IF($B17>'Constants (dont edit)'!$B$3,(SUMIF('Raw Games'!P:P,$A17,'Raw Games'!R:R)-SUMIF('Raw Games'!Q:Q,$A17,'Raw Games'!R:R)/B17)/B17,0) -> 0
A18: =('Pivot (dont edit)'!A20) -> 0 | B18: =COUNT('Pivot (dont edit)'!20:20) -> 918 | C18: =COUNTIF('Raw Games'!P:P,$A18) -> 0 | D18: =IF($B18>'Constants (dont edit)'!$B$3,C18/$B18,"") -> 0 | E18: =COUNTIF('Raw Games'!Q:Q,$A18) -> 0 | F18: =IF($B18>'Constants (dont edit)'!$B$3,E18/$B18,"") -> 0 | G18: =MIN('Pivot (dont edit)'!20:20) -> #N/A | H18: =MAX('Pivot (dont edit)'!20:20) -> #N/A | I18: =IF(AND(B18>='Constants (dont edit)'!$B$4,SUM('Pivot (dont edit)'!20:20)>0), AVERAGE('Pivot (dont edit)'!20:20), "") -> #N/A | J18: =SUM('Pivot (dont edit)'!20:20) -> #N/A | K18: =RANK(L18,L:L) -> 1 | L18: =IF($B18>'Constants (dont edit)'!$B$3,(SUMIF('Raw Games'!P:P,$A18,'Raw Games'!R:R)-SUMIF('Raw Games'!Q:Q,$A18,'Raw Games'!R:R)/B18)/B18,0) -> 0
A19: =('Pivot (dont edit)'!A21) -> 0 | B19: =COUNT('Pivot (dont edit)'!21:21) -> 918 | C19: =COUNTIF('Raw Games'!P:P,$A19) -> 0 | D19: =IF($B19>'Constants (dont edit)'!$B$3,C19/$B19,"") -> 0 | E19: =COUNTIF('Raw Games'!Q:Q,$A19) -> 0 | F19: =IF($B19>'Constants (dont edit)'!$B$3,E19/$B19,"") -> 0 | G19: =MIN('Pivot (dont edit)'!21:21) -> #N/A | H19: =MAX('Pivot (dont edit)'!21:21) -> #N/A | I19: =IF(AND(B19>='Constants (dont edit)'!$B$4,SUM('Pivot (dont edit)'!21:21)>0), AVERAGE('Pivot (dont edit)'!21:21), "") -> #N/A | J19: =SUM('Pivot (dont edit)'!21:21) -> #N/A | K19: =RANK(L19,L:L) -> 1 | L19: =IF($B19>'Constants (dont edit)'!$B$3,(SUMIF('Raw Games'!P:P,$A19,'Raw Games'!R:R)-SUMIF('Raw Games'!Q:Q,$A19,'Raw Games'!R:R)/B19)/B19,0) -> 0
A20: =('Pivot (dont edit)'!A22) -> 0 | B20: =COUNT('Pivot (dont edit)'!22:22) -> 918 | C20: =COUNTIF('Raw Games'!P:P,$A20) -> 0 | D20: =IF($B20>'Constants (dont edit)'!$B$3,C20/$B20,"") -> 0 | E20: =COUNTIF('Raw Games'!Q:Q,$A20) -> 0 | F20: =IF($B20>'Constants (dont edit)'!$B$3,E20/$B20,"") -> 0 | G20: =MIN('Pivot (dont edit)'!22:22) -> #N/A | H20: =MAX('Pivot (dont edit)'!22:22) -> #N/A | I20: =IF(AND(B20>='Constants (dont edit)'!$B$4,SUM('Pivot (dont edit)'!22:22)>0), AVERAGE('Pivot (dont edit)'!22:22), "") -> #N/A | J20: =SUM('Pivot (dont edit)'!22:22) -> #N/A | K20: =RANK(L20,L:L) -> 1 | L20: =IF($B20>'Constants (dont edit)'!$B$3,(SUMIF('Raw Games'!P:P,$A20,'Raw Games'!R:R)-SUMIF('Raw Games'!Q:Q,$A20,'Raw Games'!R:R)/B20)/B20,0) -> 0
A21: =('Pivot (dont edit)'!A23) -> 0 | B21: =COUNT('Pivot (dont edit)'!23:23) -> 918 | C21: =COUNTIF('Raw Games'!P:P,$A21) -> 0 | D21: =IF($B21>'Constants (dont edit)'!$B$3,C21/$B21,"") -> 0 | E21: =COUNTIF('Raw Games'!Q:Q,$A21) -> 0 | F21: =IF($B21>'Constants (dont edit)'!$B$3,E21/$B21,"") -> 0 | G21: =MIN('Pivot (dont edit)'!23:23) -> #N/A | H21: =MAX('Pivot (dont edit)'!23:23) -> #N/A | I21: =IF(AND(B21>='Constants (dont edit)'!$B$4,SUM('Pivot (dont edit)'!23:23)>0), AVERAGE('Pivot (dont edit)'!23:23), "") -> #N/A | J21: =SUM('Pivot (dont edit)'!23:23) -> #N/A | K21: =RANK(L21,L:L) -> 1 | L21: =IF($B21>'Constants (dont edit)'!$B$3,(SUMIF('Raw Games'!P:P,$A21,'Raw Games'!R:R)-SUMIF('Raw Games'!Q:Q,$A21,'Raw Games'!R:R)/B21)/B21,0) -> 0
A22: =('Pivot (dont edit)'!A24) -> 0 | B22: =COUNT('Pivot (dont edit)'!24:24) -> 918 | C22: =COUNTIF('Raw Games'!P:P,$A22) -> 0 | D22: =IF($B22>'Constants (dont edit)'!$B$3,C22/$B22,"") -> 0 | E22: =COUNTIF('Raw Games'!Q:Q,$A22) -> 0 | F22: =IF($B22>'Constants (dont edit)'!$B$3,E22/$B22,"") -> 0 | G22: =MIN('Pivot (dont edit)'!24:24) -> #N/A | H22: =MAX('Pivot (dont edit)'!24:24) -> #N/A | I22: =IF(AND(B22>='Constants (dont edit)'!$B$4,SUM('Pivot (dont edit)'!24:24)>0), AVERAGE('Pivot (dont edit)'!24:24), "") -> #N/A | J22: =SUM('Pivot (dont edit)'!24:24) -> #N/A | K22: =RANK(L22,L:L) -> 1 | L22: =IF($B22>'Constants (dont edit)'!$B$3,(SUMIF('Raw Games'!P:P,$A22,'Raw Games'!R:R)-SUMIF('Raw Games'!Q:Q,$A22,'Raw Games'!R:R)/B22)/B22,0) -> 0
A23: =('Pivot (dont edit)'!A25) -> 0 | B23: =COUNT('Pivot (dont edit)'!25:25) -> 918 | C23: =COUNTIF('Raw Games'!P:P,$A23) -> 0 | D23: =IF($B23>'Constants (dont edit)'!$B$3,C23/$B23,"") -> 0 | E23: =COUNTIF('Raw Games'!Q:Q,$A23) -> 0 | F23: =IF($B23>'Constants (dont edit)'!$B$3,E23/$B23,"") -> 0 | G23: =MIN('Pivot (dont edit)'!25:25) -> #N/A | H23: =MAX('Pivot (dont edit)'!25:25) -> #N/A | I23: =IF(AND(B23>='Constants (dont edit)'!$B$4,SUM('Pivot (dont edit)'!25:25)>0), AVERAGE('Pivot (dont edit)'!25:25), "") -> #N/A | J23: =SUM('Pivot (dont edit)'!25:25) -> #N/A | K23: =RANK(L23,L:L) -> 1 | L23: =IF($B23>'Constants (dont edit)'!$B$3,(SUMIF('Raw Games'!P:P,$A23,'Raw Games'!R:R)-SUMIF('Raw Games'!Q:Q,$A23,'Raw Games'!R:R)/B23)/B23,0) -> 0
A24: =('Pivot (dont edit)'!A26) -> 0 | B24: =COUNT('Pivot (dont edit)'!26:26) -> 918 | C24: =COUNTIF('Raw Games'!P:P,$A24) -> 0 | D24: =IF($B24>'Constants (dont edit)'!$B$3,C24/$B24,"") -> 0 | E24: =COUNTIF('Raw Games'!Q:Q,$A24) -> 0 | F24: =IF($B24>'Constants (dont edit)'!$B$3,E24/$B24,"") -> 0 | G24: =MIN('Pivot (dont edit)'!26:26) -> #N/A | H24: =MAX('Pivot (dont edit)'!26:26) -> #N/A | I24: =IF(AND(B24>='Constants (dont edit)'!$B$4,SUM('Pivot (dont edit)'!26:26)>0), AVERAGE('Pivot (dont edit)'!26:26), "") -> #N/A | J24: =SUM('Pivot (dont edit)'!26:26) -> #N/A | K24: =RANK(L24,L:L) -> 1 | L24: =IF($B24>'Constants (dont edit)'!$B$3,(SUMIF('Raw Games'!P:P,$A24,'Raw Games'!R:R)-SUMIF('Raw Games'!Q:Q,$A24,'Raw Games'!R:R)/B24)/B24,0) -> 0
A25: =('Pivot (dont edit)'!A27) -> 0 | B25: =COUNT('Pivot (dont edit)'!27:27) -> 918 | C25: =COUNTIF('Raw Games'!P:P,$A25) -> 0 | D25: =IF($B25>'Constants (dont edit)'!$B$3,C25/$B25,"") -> 0 | E25: =COUNTIF('Raw Games'!Q:Q,$A25) -> 0 | F25: =IF($B25>'Constants (dont edit)'!$B$3,E25/$B25,"") -> 0 | G25: =MIN('Pivot (dont edit)'!27:27) -> #N/A | H25: =MAX('Pivot (dont edit)'!27:27) -> #N/A | I25: =IF(AND(B25>='Constants (dont edit)'!$B$4,SUM('Pivot (dont edit)'!27:27)>0), AVERAGE('Pivot (dont edit)'!27:27), "") -> #N/A | J25: =SUM('Pivot (dont edit)'!27:27) -> #N/A | K25: =RANK(L25,L:L) -> 1 | L25: =IF($B25>'Constants (dont edit)'!$B$3,(SUMIF('Raw Games'!P:P,$A25,'Raw Games'!R:R)-SUMIF('Raw Games'!Q:Q,$A25,'Raw Games'!R:R)/B25)/B25,0) -> 0 | M25: =('Pivot (dont edit)'!M27) -> 0 | N25: =COUNT('Pivot (dont edit)'!27:27) -> 918 | O25: =COUNTIF('Raw Games'!AB:AB,$A25) -> 0 | P25: =IF($B25>'Constants (dont edit)'!$B$3,O25/$B25,"") -> 0 | Q25: =COUNTIF('Raw Games'!AC:AC,$A25) -> 0 | R25: =IF($B25>'Constants (dont edit)'!$B$3,Q25/$B25,"") -> 0 | S25: =MIN('Pivot (dont edit)'!27:27) -> #N/A | T25: =MAX('Pivot (dont edit)'!27:27) -> #N/A | U25: =IF(AND(N25>='Constants (dont edit)'!$B$4,SUM('Pivot (dont edit)'!27:27)>0), AVERAGE('Pivot (dont edit)'!27:27), "") -> #N/A | V25: =SUM('Pivot (dont edit)'!27:27) -> #N/A | W25: =RANK(X25,X:X) -> 1 | X25: =IF($B25>'Constants (dont edit)'!$B$3,(SUMIF('Raw Games'!AB:AB,$A25,'Raw Games'!AD:AD)-SUMIF('Raw Games'!AC:AC,$A25,'Raw Games'!AD:AD)/N25)/N25,0) -> 0 | Y25: =('Pivot (dont edit)'!Y27) -> 0 | Z25: =COUNT('Pivot (dont edit)'!27:27) -> 918 | AA25: =COUNTIF('Raw Games'!AN:AN,$A25) -> 0 | AB25: =IF($B25>'Constants (dont edit)'!$B$3,AA25/$B25,"") -> 0 | AC25: =COUNTIF('Raw Games'!AO:AO,$A25) -> 0 | AD25: =IF($B25>'Constants (dont edit)'!$B$3,AC25/$B25,"") -> 0 | AE25: =MIN('Pivot (dont edit)'!27:27) -> #N/A | AF25: =MAX('Pivot (dont edit)'!27:27) -> #N/A
A26: =('Pivot (dont edit)'!A28) -> 0 | B26: =COUNT('Pivot (dont edit)'!28:28) -> 918 | C26: =COUNTIF('Raw Games'!P:P,$A26) -> 0 | D26: =IF($B26>'Constants (dont edit)'!$B$3,C26/$B26,"") -> 0 | E26: =COUNTIF('Raw Games'!Q:Q,$A26) -> 0 | F26: =IF($B26>'Constants (dont edit)'!$B$3,E26/$B26,"") -> 0 | G26: =MIN('Pivot (dont edit)'!28:28) -> #N/A | H26: =MAX('Pivot (dont edit)'!28:28) -> #N/A | I26: =IF(AND(B26>='Constants (dont edit)'!$B$4,SUM('Pivot (dont edit)'!28:28)>0), AVERAGE('Pivot (dont edit)'!28:28), "") -> #N/A | J26: =SUM('Pivot (dont edit)'!28:28) -> #N/A | K26: =RANK(L26,L:L) -> 1 | L26: =IF($B26>'Constants (dont edit)'!$B$3,(SUMIF('Raw Games'!P:P,$A26,'Raw Games'!R:R)-SUMIF('Raw Games'!Q:Q,$A26,'Raw Games'!R:R)/B26)/B26,0) -> 0 | M26: =('Pivot (dont edit)'!M28) -> 0 | N26: =COUNT('Pivot (dont edit)'!28:28) -> 918 | O26: =COUNTIF('Raw Games'!AB:AB,$A26) -> 0 | P26: =IF($B26>'Constants (dont edit)'!$B$3,O26/$B26,"") -> 0 | Q26: =COUNTIF('Raw Games'!AC:AC,$A26) -> 0 | R26: =IF($B26>'Constants (dont edit)'!$B$3,Q26/$B26,"") -> 0 | S26: =MIN('Pivot (dont edit)'!28:28) -> #N/A | T26: =MAX('Pivot (dont edit)'!28:28) -> #N/A | U26: =IF(AND(N26>='Constants (dont edit)'!$B$4,SUM('Pivot (dont edit)'!28:28)>0), AVERAGE('Pivot (dont edit)'!28:28), "") -> #N/A | V26: =SUM('Pivot (dont edit)'!28:28) -> #N/A | W26: =RANK(X26,X:X) -> 1 | X26: =IF($B26>'Constants (dont edit)'!$B$3,(SUMIF('Raw Games'!AB:AB,$A26,'Raw Games'!AD:AD)-SUMIF('Raw Games'!AC:AC,$A26,'Raw Games'!AD:AD)/N26)/N26,0) -> 0 | Y26: =('Pivot (dont edit)'!Y28) -> 0 | Z26: =COUNT('Pivot (dont edit)'!28:28) -> 918 | AA26: =COUNTIF('Raw Games'!AN:AN,$A26) -> 0 | AB26: =IF($B26>'Constants (dont edit)'!$B$3,AA26/$B26,"") -> 0 | AC26: =COUNTIF('Raw Games'!AO:AO,$A26) -> 0 | AD26: =IF($B26>'Constants (dont edit)'!$B$3,AC26/$B26,"") -> 0 | AE26: =MIN('Pivot (dont edit)'!28:28) -> #N/A | AF26: =MAX('Pivot (dont edit)'!28:28) -> #N/A
A27: =('Pivot (dont edit)'!A29) -> 0 | B27: =COUNT('Pivot (dont edit)'!29:29) -> 918 | C27: =COUNTIF('Raw Games'!P:P,$A27) -> 0 | D27: =IF($B27>'Constants (dont edit)'!$B$3,C27/$B27,"") -> 0 | E27: =COUNTIF('Raw Games'!Q:Q,$A27) -> 0 | F27: =IF($B27>'Constants (dont edit)'!$B$3,E27/$B27,"") -> 0 | G27: =MIN('Pivot (dont edit)'!29:29) -> #N/A | H27: =MAX('Pivot (dont edit)'!29:29) -> #N/A | I27: =IF(AND(B27>='Constants (dont edit)'!$B$4,SUM('Pivot (dont edit)'!29:29)>0), AVERAGE('Pivot (dont edit)'!29:29), "") -> #N/A | J27: =SUM('Pivot (dont edit)'!29:29) -> #N/A | K27: =RANK(L27,L:L) -> 1 | L27: =IF($B27>'Constants (dont edit)'!$B$3,(SUMIF('Raw Games'!P:P,$A27,'Raw Games'!R:R)-SUMIF('Raw Games'!Q:Q,$A27,'Raw Games'!R:R)/B27)/B27,0) -> 0 | M27: =('Pivot (dont edit)'!M29) -> 0 | N27: =COUNT('Pivot (dont edit)'!29:29) -> 918 | O27: =COUNTIF('Raw Games'!AB:AB,$A27) -> 0 | P27: =IF($B27>'Constants (dont edit)'!$B$3,O27/$B27,"") -> 0 | Q27: =COUNTIF('Raw Games'!AC:AC,$A27) -> 0 | R27: =IF($B27>'Constants (dont edit)'!$B$3,Q27/$B27,"") -> 0 | S27: =MIN('Pivot (dont edit)'!29:29) -> #N/A | T27: =MAX('Pivot (dont edit)'!29:29) -> #N/A | U27: =IF(AND(N27>='Constants (dont edit)'!$B$4,SUM('Pivot (dont edit)'!29:29)>0), AVERAGE('Pivot (dont edit)'!29:29), "") -> #N/A | V27: =SUM('Pivot (dont edit)'!29:29) -> #N/A | W27: =RANK(X27,X:X) -> 1 | X27: =IF($B27>'Constants (dont edit)'!$B$3,(SUMIF('Raw Games'!AB:AB,$A27,'Raw Games'!AD:AD)-SUMIF('Raw Games'!AC:AC,$A27,'Raw Games'!AD:AD)/N27)/N27,0) -> 0 | Y27: =('Pivot (dont edit)'!Y29) -> 0 | Z27: =COUNT('Pivot (dont edit)'!29:29) -> 918 | AA27: =COUNTIF('Raw Games'!AN:AN,$A27) -> 0 | AB27: =IF($B27>'Constants (dont edit)'!$B$3,AA27/$B27,"") -> 0 | AC27: =COUNTIF('Raw Games'!AO:AO,$A27) -> 0 | AD27: =IF($B27>'Constants (dont edit)'!$B$3,AC27/$B27,"") -> 0 | AE27: =MIN('Pivot (dont edit)'!29:29) -> #N/A | AF27: =MAX('Pivot (dont edit)'!29:29) -> #N/A
A28: =('Pivot (dont edit)'!A30) -> 0 | B28: =COUNT('Pivot (dont edit)'!30:30) -> 918 | C28: =COUNTIF('Raw Games'!P:P,$A28) -> 0 | D28: =IF($B28>'Constants (dont edit)'!$B$3,C28/$B28,"") -> 0 | E28: =COUNTIF('Raw Games'!Q:Q,$A28) -> 0 | F28: =IF($B28>'Constants (dont edit)'!$B$3,E28/$B28,"") -> 0 | G28: =MIN('Pivot (dont edit)'!30:30) -> #N/A | H28: =MAX('Pivot (dont edit)'!30:30) -> #N/A | I28: =IF(AND(B28>='Constants (dont edit)'!$B$4,SUM('Pivot (dont edit)'!30:30)>0), AVERAGE('Pivot (dont edit)'!30:30), "") -> #N/A | J28: =SUM('Pivot (dont edit)'!30:30) -> #N/A | K28: =RANK(L28,L:L) -> 1 | L28: =IF($B28>'Constants (dont edit)'!$B$3,(SUMIF('Raw Games'!P:P,$A28,'Raw Games'!R:R)-SUMIF('Raw Games'!Q:Q,$A28,'Raw Games'!R:R)/B28)/B28,0) -> 0 | M28: =('Pivot (dont edit)'!M30) -> 0 | N28: =COUNT('Pivot (dont edit)'!30:30) -> 918 | O28: =COUNTIF('Raw Games'!AB:AB,$A28) -> 0 | P28: =IF($B28>'Constants (dont edit)'!$B$3,O28/$B28,"") -> 0 | Q28: =COUNTIF('Raw Games'!AC:AC,$A28) -> 0 | R28: =IF($B28>'Constants (dont edit)'!$B$3,Q28/$B28,"") -> 0 | S28: =MIN('Pivot (dont edit)'!30:30) -> #N/A | T28: =MAX('Pivot (dont edit)'!30:30) -> #N/A | U28: =IF(AND(N28>='Constants (dont edit)'!$B$4,SUM('Pivot (dont edit)'!30:30)>0), AVERAGE('Pivot (dont edit)'!30:30), "") -> #N/A | V28: =SUM('Pivot (dont edit)'!30:30) -> #N/A | W28: =RANK(X28,X:X) -> 1 | X28: =IF($B28>'Constants (dont edit)'!$B$3,(SUMIF('Raw Games'!AB:AB,$A28,'Raw Games'!AD:AD)-SUMIF('Raw Games'!AC:AC,$A28,'Raw Games'!AD:AD)/N28)/N28,0) -> 0 | Y28: =('Pivot (dont edit)'!Y30) -> 0 | Z28: =COUNT('Pivot (dont edit)'!30:30) -> 918 | AA28: =COUNTIF('Raw Games'!AN:AN,$A28) -> 0 | AB28: =IF($B28>'Constants (dont edit)'!$B$3,AA28/$B28,"") -> 0 | AC28: =COUNTIF('Raw Games'!AO:AO,$A28) -> 0 | AD28: =IF($B28>'Constants (dont edit)'!$B$3,AC28/$B28,"") -> 0 | AE28: =MIN('Pivot (dont edit)'!30:30) -> #N/A | AF28: =MAX('Pivot (dont edit)'!30:30) -> #N/A
A29: =('Pivot (dont edit)'!A31) -> 0 | B29: =COUNT('Pivot (dont edit)'!31:31) -> 918 | C29: =COUNTIF('Raw Games'!P:P,$A29) -> 0 | D29: =IF($B29>'Constants (dont edit)'!$B$3,C29/$B29,"") -> 0 | E29: =COUNTIF('Raw Games'!Q:Q,$A29) -> 0 | F29: =IF($B29>'Constants (dont edit)'!$B$3,E29/$B29,"") -> 0 | G29: =MIN('Pivot (dont edit)'!31:31) -> #N/A | H29: =MAX('Pivot (dont edit)'!31:31) -> #N/A | I29: =IF(AND(B29>='Constants (dont edit)'!$B$4,SUM('Pivot (dont edit)'!31:31)>0), AVERAGE('Pivot (dont edit)'!31:31), "") -> #N/A | J29: =SUM('Pivot (dont edit)'!31:31) -> #N/A | K29: =RANK(L29,L:L) -> 1 | L29: =IF($B29>'Constants (dont edit)'!$B$3,(SUMIF('Raw Games'!P:P,$A29,'Raw Games'!R:R)-SUMIF('Raw Games'!Q:Q,$A29,'Raw Games'!R:R)/B29)/B29,0) -> 0 | M29: =('Pivot (dont edit)'!M31) -> 0 | N29: =COUNT('Pivot (dont edit)'!31:31) -> 918 | O29: =COUNTIF('Raw Games'!AB:AB,$A29) -> 0 | P29: =IF($B29>'Constants (dont edit)'!$B$3,O29/$B29,"") -> 0 | Q29: =COUNTIF('Raw Games'!AC:AC,$A29) -> 0 | R29: =IF($B29>'Constants (dont edit)'!$B$3,Q29/$B29,"") -> 0 | S29: =MIN('Pivot (dont edit)'!31:31) -> #N/A | T29: =MAX('Pivot (dont edit)'!31:31) -> #N/A | U29: =IF(AND(N29>='Constants (dont edit)'!$B$4,SUM('Pivot (dont edit)'!31:31)>0), AVERAGE('Pivot (dont edit)'!31:31), "") -> #N/A | V29: =SUM('Pivot (dont edit)'!31:31) -> #N/A | W29: =RANK(X29,X:X) -> 1 | X29: =IF($B29>'Constants (dont edit)'!$B$3,(SUMIF('Raw Games'!AB:AB,$A29,'Raw Games'!AD:AD)-SUMIF('Raw Games'!AC:AC,$A29,'Raw Games'!AD:AD)/N29)/N29,0) -> 0 | Y29: =('Pivot (dont edit)'!Y31) -> 0 | Z29: =COUNT('Pivot (dont edit)'!31:31) -> 918 | AA29: =COUNTIF('Raw Games'!AN:AN,$A29) -> 0 | AB29: =IF($B29>'Constants (dont edit)'!$B$3,AA29/$B29,"") -> 0 | AC29: =COUNTIF('Raw Games'!AO:AO,$A29) -> 0 | AD29: =IF($B29>'Constants (dont edit)'!$B$3,AC29/$B29,"") -> 0 | AE29: =MIN('Pivot (dont edit)'!31:31) -> #N/A | AF29: =MAX('Pivot (dont edit)'!31:31) -> #N/A

Sheet Constants (dont edit)
A1: Name | B1: Value
A2: Constants
A3: Minimum Number of Games for stats | B3: 15
A4: Minimum Number of Games for avg | B4: 3
A5: Rank Factor | B5: 1000
A7: Global Stats
A8: Total Game Count | B8: =COUNTA('Raw Games'!A:A)-1 -> 434
A9: Full Game Count | B9: =B8-B10 -> 404
A10: Half Game Count | B10: =COUNTIF('Raw Games'!C:C,"=Yes") -> 30
A11: Overall average score | B11: =AVERAGE('Raw Games'!E:M) -> 427.11398
A12: All time maximum score | B12: =MAX('Raw Games'!E:M) -> 1310
A13: All time minimum score | B13: =MIN('Raw Games'!E:M) -> 5
A14: Scores over 1000 | B14: =COUNTIF('Raw Games'!E:M,">=1000") -> 17
A16: README
A17: 1. In 'Raw Games' sheet, be sure to keep Min, Max, Winner, Loser data filled downward at least as far as the game data rows.
A18: 2. In 'Raw Games' sheet, when winners and losers stop getting highlighted, you need to Edit > Paste Special > Conditional Formatting those rows and below after copying to clipboard the last highlighted row.
A19: 3. Adding a new person is a two stop process: 1) insert a column in the alphabetical location for the new person, and b) Navigate to "Stats" page and fill downward to reveal last person.
A20: 4. Inserting a new person whose name starts with A and is before the current first person is difficult because all the Conditions and Formulae will point to the column after. You will have to edit all of them.
A21: 5. To add new Game results, add them after the last row in the "Raw Games" sheet (curently at over 250 rows)
A22: 6. Once there are over 1001 rows in 'Raw Games' we will have to a) add Columns to the 'Pivot' sheet and b) Modify the TRANSPOSE function in Pivot!A:1 to include the additional columns.

Sheet Pivot (dont edit)
A1: {=TRANSPOSE('Raw Games'!1:918)} -> Date | B1: 43134 | C1: 43135 | D1: 43136 | E1: 43137 | F1: 43138 | G1: 43140 | H1: 43142 | I1: 43144 | J1: 43146 | K1: 43148 | L1: 43150 | M1: 43152 | N1: 43154 | O1: 43156 | P1: 43158 | Q1: 43160 | R1: 43162 | S1: 43164 | T1: 43289 | U1: 43291 | V1: 43293 | W1: 43295 | X1: 43297 | Y1: 43299 | Z1: 43301 | AA1: 43303 | AB1: 43305 | AC1: 43307 | AD1: 43309 | AE1: 43311 | AF1: 43313 | AG1: 43315 | AH1: 43317 | AI1: 43319 | AJ1: 43321 | AK1: 43323 | AL1: 43325 | AM1: 43327 | AN1: 43415 | AO1: 43417 | AP1: 43419 | AQ1: 43421 | AR1: 43423 | AS1: 43425 | AT1: 43427 | AU1: 43429 | AV1: 43431 | AW1: 43433 | AX1: 43435 | AY1: 43498 | AZ1: 43500 | BA1: 43502 | BB1: 43504 | BC1: 43506 | BD1: 43508 | BE1: 43510 | BF1: 43512 | BG1: 43514 | BH1: 43516 | BI1: 43518 | BJ1: 43520 | BK1: 43592 | BL1: 43594 | BM1: 43596 | BN1: 43598 | BO1: 43600 | BP1: 43602 | BQ1: 43604 | BR1: 43606 | BS1: 43608 | BT1: 43610 | BU1: 43612 | BV1: 43614 | BW1: 43616 | BX1: 44062 | BY1: 44064 | BZ1: 44066 | CA1: 44068 | CB1: 44070 | CC1: 44072 | CD1: 44074 | CE1: 44076 | CF1: 44078 | CG1: 44080 | CH1: 44082 | CI1: 44084 | CJ1: 44086 | CK1: 43834 | CL1: 43836 | CM1: 43838 | CN1: 43840 | CO1: 43842 | CP1: 43844 | CQ1: 43846 | CR1: 43848 | CS1: 43850 | CT1: 44065 | CU1: 44067 | CV1: 44069 | CW1: 44071 | CX1: 44073 | CY1: 44075 | CZ1: 44077 | DA1: 44079 | DB1: 44081 | DC1: 44083 | DD1: 44087 | DE1: 44089 | DF1: 44098 | DG1: 44100 | DH1: 44108 | DI1: 44112 | DJ1: 44114 | DK1: 44127 | DL1: 44129 | DM1: 44137 | DN1: 44140 | DO1: 44142 | DP1: 44146 | DQ1: 44148 | DR1: 44156 | DS1: 44158 | DT1: 44164 | DU1: 44170 | DV1: 44170 | DW1: 44173 | DX1: 44175 | DY1: 44176 | DZ1: 44183 | EA1: 44200 | EB1: 44206 | EC1: 44210 | ED1: 44239 | EE1: 44240 | EF1: 44242 | EG1: 44267 | EH1: 44272 | EI1: 44274 | EJ1: 44279 | EK1: 44281 | EL1: 44285 | EM1: 44288 | EN1: 44292 | EO1: 44297 | EP1: 44297 | EQ1: 44297 | ER1: 44298 | ES1: 44299 | ET1: 44300 | EU1: 44302 | EV1: 44307 | EW1: 44318 | EX1: 44329 | EY1: 44342 | EZ1: 44344 | FA1: 44346 | FB1: 44347 | FC1: 44352 | FD1: 44362 | FE1: 44370 | FF1: 44374 | FG1: 44375 | FH1: 44416 | FI1: 44422 | FJ1: 44423 | FK1: 44428 | FL1: 44437 | FM1: 44500 | FN1: 44538 | FO1: 44539 | FP1: 44562 | FQ1: 44581 | FR1: 44595 | FS1: 44602 | FT1: 44623 | FU1: 44665 | FV1: 44673 | FW1: 44679 | FX1: 44681 | FY1: 44686 | FZ1: 44688 | GA1: 44700 | GB1: 44702 | GC1: 44709 | GD1: 44711 | GE1: 44712 | GF1: 44751 | GG1: 44787 | GH1: 44791 | GI1: 44793 | GJ1: 44798 | GK1: 44815 | GL1: 44819 | GM1: 44836 | GN1: 44850 | GO1: 44852 | GP1: 44864 | GQ1: 44870 | GR1: 44871 | GS1: 44875 | GT1: 44878 | GU1: 44880 | GV1: 44896 | GW1: 44903 | GX1: 44927 | GY1: 44933 | GZ1: 44938 | HA1: 44945 | HB1: 44954 | HC1: 44961 | HD1: 44966 | HE1: 44968 | HF1: 44989 | HG1: 44990 | HH1: 44996 | HI1: 44999 | HJ1: 45001 | HK1: 45003 | HL1: 45008 | HM1: 45008 | HN1: 45010 | HO1: 45022 | HP1: 45025 | HQ1: 45027 | HR1: 45029 | HS1: 45031 | HT1: 45031 | HU1: 45043 | HV1: 45045 | HW1: 45051 | HX1: 45057 | HY1: 45066 | HZ1: 45071 | IA1: 45073 | IB1: 45074 | IC1: 45089 | ID1: 45092 | IE1: 45094 | IF1: 45099 | IG1: 45106 | IH1: 45107 | II1: 45109 | IJ1: 45110 | IK1: 45111 | IL1: 45113 | IM1: 45116 | IN1: 45126 | IO1: 45134 | IP1: 45143 | IQ1: 45147 | IR1: 45148 | IS1: 45150 | IT1: 45155 | IU1: 45156 | IV1: 45158 | IW1: 45162 | IX1: 45167 | IY1: 45170 | IZ1: 45178 | JA1: 45181 | JB1: 45184 | JC1: 45185 | JD1: 45187 | JE1: 45190 | JF1: 45191 | JG1: 45192 | JH1: 45193 | JI1: 45194 | JJ1: 45197 | JK1: 45206 | JL1: 45218 | JM1: 45232 | JN1: 45237 | JO1: 45240 | JP1: 45242 | JQ1: 45243 | JR1: 45245 | JS1: 45246 | JT1: 45254 | JU1: 45255 | JV1: 45256 | JW1: 45259 | JX1: 45262 | JY1: 45272 | JZ1: 45274 | KA1: 45278 | KB1: 45281 | KC1: 45287 | KD1: 45291 | KE1: 45302 | KF1: 45309 | KG1: 45311 | KH1: 45323 | KI1: 45325 | KJ1: 45330 | KK1: 45332 | KL1: 45337 | KM1: 45339 | KN1: 45351 | KO1: 45353 | KP1: 45358 | KQ1: 45360 | KR1: 45364 | KS1: 45367 | KT1: 45372 | KU1: 45380 | KV1: 45381 | KW1: 45392 | KX1: 45393 | KY1: 45395 | KZ1: 45397 | LA1: 45398 | LB1: 45391 | LC1: 45407 | LD1: 45416 | LE1: 45424 | LF1: 45426 | LG1: 45430 | LH1: 45438 | LI1: 45444 | LJ1: 45451 | LK1: 45471 | LL1: 45476 | LM1: 45481 | LN1: 45485 | LO1: 45486 | LP1: 45493 | LQ1: 45494 | LR1: 45497 | LS1: 45498 | LT1: 45516 | LU1: 45521 | LV1: 45534 | LW1: 45536 | LX1: 45598 | LY1: 45611 | LZ1: 45619 | MA1: 45624 | MB1: 45633 | MC1: 45641 | MD1: 45654 | ME1: 45657 | MF1: 45661 | MG1: 45664 | MH1: 45668 | MI1: 45675 | MJ1: 45683 | MK1: 45690 | ML1: 45696 | MM1: 45699 | MN1: 45704 | MO1: 45711 | MP1: 45719 | MQ1: 45723 | MR1: 45731 | MS1: 45743 | MT1: 45745 | MU1: 45752 | MV1: 45754 | MW1: 45757 | MX1: 45758 | MY1: 45759 | MZ1: 45764 | NA1: 45772 | NB1: 45773 | NC1: 45774 | ND1: 45775 | NE1: 45785 | NF1: 45788 | NG1: 45799 | NH1: 45801 | NI1: 45807 | NJ1: 45815 | NK1: 45821 | NL1: 45823 | NM1: 45836 | NN1: 45837 | NO1: 45838 | NP1: 45841 | NQ1: 45842 | NR1: 45844 | NS1: 45845 | NT1: 45853 | NU1: 45875 | NV1: 45879 | NW1: 45881 | NX1: 45885 | NY1: 45886 | NZ1: 45889 | OA1: 45892 | OB1: 45897 | OC1: 45898 | OD1: 45899 | OE1: 45900 | OF1: 45903 | OG1: 45906 | OH1: 45914 | OI1: 45917 | OJ1: 45924 | OK1: 45930 | OL1: 45931 | OM1: 45934 | ON1: 45941 | OO1: 45948 | OP1: 45966 | OQ1: 45968 | OR1: 45969 | OS1: 45970 | OT1: 45976 | OU1: 45983 | OV1: 45983 | OW1: 45990 | OX1: 45991 | OY1: 45994 | OZ1: 45997 | PA1: 46023 | PB1: 46025 | PC1: 46032 | PD1: 46039 | PE1: 46050 | PF1: 46067 | PG1: 46081 | PH1: 46084 | PI1: 46085 | PJ1: 46089 | PK1: 46091 | PL1: 46109 | PM1: 46121 | PN1: 46137 | PO1: 46156 | PP1: 46159 | PQ1: 46160 | PR1: 46167 | PS1: 46186 | PT1: 0 | PU1: 0 | PV1: 0 | PW1: 0 | PX1: 0 | PY1: 0 | PZ1: 0 | QA1: 0 | QB1: 0 | QC1: 0 | QD1: 0 | QE1: 0 | QF1: 0 | QG1: 0 | QH1: 0 | QI1: 0 | QJ1: 0 | QK1: 0 | QL1: 0 | QM1: 0 | QN1: 0 | QO1: 0 | QP1: 0 | QQ1: 0 | QR1: 0 | QS1: 0 | QT1: 0 | QU1: 0 | QV1: 0 | QW1: 0 | QX1: 0 | QY1: 0 | QZ1: 0 | RA1: 0 | RB1: 0 | RC1: 0 | RD1: 0 | RE1: 0 | RF1: 0 | RG1: 0 | RH1: 0 | RI1: 0 | RJ1: 0 | RK1: 0 | RL1: 0 | RM1: 0 | RN1: 0 | RO1: 0 | RP1: 0 | RQ1: 0 | RR1: 0 | RS1: 0 | RT1: 0 | RU1: 0 | RV1: 0 | RW1: 0 | RX1: 0 | RY1: 0 | RZ1: 0 | SA1: 0 | SB1: 0 | SC1: 0 | SD1: 0 | SE1: 0 | SF1: 0 | SG1: 0 | SH1: 0 | SI1: 0 | SJ1: 0 | SK1: 0 | SL1: 0 | SM1: 0 | SN1: 0 | SO1: 0 | SP1: 0 | SQ1: 0 | SR1: 0 | SS1: 0 | ST1: 0 | SU1: 0 | SV1: 0 | SW1: 0 | SX1: 0 | SY1: 0 | SZ1: 0 | TA1: 0 | TB1: 0 | TC1: 0 | TD1: 0 | TE1: 0 | TF1: 0 | TG1: 0 | TH1: 0 | TI1: 0 | TJ1: 0 | TK1: 0 | TL1: 0 | TM1: 0 | TN1: 0 | TO1: 0 | TP1: 0 | TQ1: 0 | TR1: 0 | TS1: 0 | TT1: 0 | TU1: 0 | TV1: 0 | TW1: 0 | TX1: 0 | TY1: 0 | TZ1: 0 | UA1: 0 | UB1: 0 | UC1: 0 | UD1: 0 | UE1: 0 | UF1: 0 | UG1: 0 | UH1: 0 | UI1: 0 | UJ1: 0 | UK1: 0 | UL1: 0 | UM1: 0 | UN1: 0 | UO1: 0 | UP1: 0 | UQ1: 0 | UR1: 0 | US1: 0 | UT1: 0 | UU1: 0 | UV1: 0 | UW1: 0 | UX1: 0 | UY1: 0 | UZ1: 0 | VA1: 0 | VB1: 0 | VC1: 0 | VD1: 0 | VE1: 0 | VF1: 0 | VG1: 0 | VH1: 0 | VI1: 0 | VJ1: 0 | VK1: 0 | VL1: 0 | VM1: 0 | VN1: 0 | VO1: 0 | VP1: 0 | VQ1: 0 | VR1: 0 | VS1: 0 | VT1: 0 | VU1: 0 | VV1: 0 | VW1: 0 | VX1: 0 | VY1: 0 | VZ1: 0 | WA1: 0 | WB1: 0 | WC1: 0 | WD1: 0 | WE1: 0 | WF1: 0 | WG1: 0 | WH1: 0 | WI1: 0 | WJ1: 0 | WK1: 0 | WL1: 0 | WM1: 0 | WN1: 0 | WO1: 0 | WP1: 0 | WQ1: 0 | WR1: 0 | WS1: 0 | WT1: 0 | WU1: 0 | WV1: 0 | WW1: 0 | WX1: 0 | WY1: 0 | WZ1: 0 | XA1: 0 | XB1: 0 | XC1: 0 | XD1: 0 | XE1: 0 | XF1: 0 | XG1: 0 | XH1: 0 | XI1: 0 | XJ1: 0 | XK1: 0 | XL1: 0 | XM1: 0 | XN1: 0 | XO1: 0 | XP1: 0 | XQ1: 0 | XR1: 0 | XS1: 0 | XT1: 0 | XU1: 0 | XV1: 0 | XW1: 0 | XX1: 0 | XY1: 0 | XZ1: 0 | YA1: 0 | YB1: 0 | YC1: 0 | YD1: 0 | YE1: 0 | YF1: 0 | YG1: 0 | YH1: 0 | YI1: 0 | YJ1: 0 | YK1: 0 | YL1: 0 | YM1: 0 | YN1: 0 | YO1: 0 | YP1: 0 | YQ1: 0 | YR1: 0 | YS1: 0 | YT1: 0 | YU1: 0 | YV1: 0 | YW1: 0 | YX1: 0 | YY1: 0 | YZ1: 0 | ZA1: 0 | ZB1: 0 | ZC1: 0 | ZD1: 0 | ZE1: 0 | ZF1: 0 | ZG1: 0 | ZH1: 0 | ZI1: 0 | ZJ1: 0 | ZK1: 0 | ZL1: 0 | ZM1: 0 | ZN1: 0 | ZO1: 0 | ZP1: 0 | ZQ1: 0 | ZR1: 0 | ZS1: 0 | ZT1: 0 | ZU1: 0 | ZV1: 0 | ZW1: 0 | ZX1: 0 | ZY1: 0 | ZZ1: 0 | AAA1: 0 | AAB1: 0 | AAC1: 0 | AAD1: 0 | AAE1: 0 | AAF1: 0 | AAG1: 0 | AAH1: 0 | AAI1: 0 | AAJ1: 0 | AAK1: 0 | AAL1: 0 | AAM1: 0 | AAN1: 0 | AAO1: 0 | AAP1: 0 | AAQ1: 0 | AAR1: 0 | AAS1: 0 | AAT1: 0 | AAU1: 0 | AAV1: 0 | AAW1: 0 | AAX1: 0 | AAY1: 0 | AAZ1: 0 | ABA1: 0 | ABB1: 0 | ABC1: 0 | ABD1: 0 | ABE1: 0 | ABF1: 0 | ABG1: 0 | ABH1: 0 | ABI1: 0 | ABJ1: 0 | ABK1: 0 | ABL1: 0 | ABM1: 0 | ABN1: 0 | ABO1: 0 | ABP1: 0 | ABQ1: 0 | ABR1: 0 | ABS1: 0 | ABT1: 0 | ABU1: 0 | ABV1: 0 | ABW1: 0 | ABX1: 0 | ABY1: 0 | ABZ1: 0 | ACA1: 0 | ACB1: 0 | ACC1: 0 | ACD1: 0 | ACE1: 0 | ACF1: 0 | ACG1: 0 | ACH1: 0 | ACI1: 0 | ACJ1: 0 | ACK1: 0 | ACL1: 0 | ACM1: 0 | ACN1: 0 | ACO1: 0 | ACP1: 0 | ACQ1: 0 | ACR1: 0 | ACS1: 0 | ACT1: 0 | ACU1: 0 | ACV1: 0 | ACW1: 0 | ACX1: 0 | ACY1: 0 | ACZ1: 0 | ADA1: 0 | ADB1: 0 | ADC1: 0 | ADD1: 0 | ADE1: 0 | ADF1: 0 | ADG1: 0 | ADH1: 0 | ADI1: 0 | ADJ1: 0 | ADK1: 0 | ADL1: 0 | ADM1: 0 | ADN1: 0 | ADO1: 0 | ADP1: 0 | ADQ1: 0 | ADR1: 0 | ADS1: 0 | ADT1: 0 | ADU1: 0 | ADV1: 0 | ADW1: 0 | ADX1: 0 | ADY1: 0 | ADZ1: 0 | AEA1: 0 | AEB1: 0 | AEC1: 0 | AED1: 0 | AEE1: 0 | AEF1: 0 | AEG1: 0 | AEH1: 0 | AEI1: 0 | AEJ1: 0 | AEK1: 0 | AEL1: 0 | AEM1: 0 | AEN1: 0 | AEO1: 0 | AEP1: 0 | AEQ1: 0 | AER1: 0 | AES1: 0 | AET1: 0 | AEU1: 0 | AEV1: 0 | AEW1: 0 | AEX1: 0 | AEY1: 0 | AEZ1: 0 | AFA1: 0 | AFB1: 0 | AFC1: 0 | AFD1: 0 | AFE1: 0 | AFF1: 0 | AFG1: 0 | AFH1: 0 | AFI1: 0 | AFJ1: 0 | AFK1: 0 | AFL1: 0 | AFM1: 0 | AFN1: 0 | AFO1: 0 | AFP1: 0 | AFQ1: 0 | AFR1: 0 | AFS1: 0 | AFT1: 0 | AFU1: 0 | AFV1: 0 | AFW1: 0 | AFX1: 0 | AFY1: 0 | AFZ1: 0 | AGA1: 0 | AGB1: 0 | AGC1: 0 | AGD1: 0 | AGE1: 0 | AGF1: 0 | AGG1: 0 | AGH1: 0 | AGI1: 0 | AGJ1: 0 | AGK1: 0 | AGL1: 0 | AGM1: 0 | AGN1: 0 | AGO1: 0 | AGP1: 0 | AGQ1: 0 | AGR1: 0 | AGS1: 0 | AGT1: 0 | AGU1: 0 | AGV1: 0 | AGW1: 0 | AGX1: 0 | AGY1: 0 | AGZ1: 0 | AHA1: 0 | AHB1: 0 | AHC1: 0 | AHD1: 0 | AHE1: 0 | AHF1: 0 | AHG1: 0 | AHH1: 0 | AHI1: 0 | AHJ1: 0 | AHK1: 0 | AHL1: 0 | AHM1: 0 | AHN1: 0 | AHO1: 0 | AHP1: 0 | AHQ1: 0 | AHR1: 0 | AHS1: 0 | AHT1: 0 | AHU1: 0 | AHV1: 0 | AHW1: 0 | AHX1: 0 | AHY1: 0 | AHZ1: 0 | AIA1: 0 | AIB1: 0 | AIC1: 0 | AID1: 0 | AIE1: 0 | AIF1: 0 | AIG1: 0 | AIH1: 0 | AII1: #N/A | AIJ1: #N/A | AIK1: #N/A | AIL1: #N/A | AIM1: #N/A | AIN1: #N/A | AIO1: #N/A | AIP1: #N/A | AIQ1: #N/A | AIR1: #N/A | AIS1: #N/A | AIT1: #N/A | AIU1: #N/A | AIV1: #N/A | AIW1: #N/A | AIX1: #N/A | AIY1: #N/A | AIZ1: #N/A | AJA1: #N/A | AJB1: #N/A | AJC1: #N/A | AJD1: #N/A | AJE1: #N/A | AJF1: #N/A | AJG1: #N/A | AJH1: #N/A | AJI1: #N/A | AJJ1: #N/A | AJK1: #N/A | AJL1: #N/A | AJM1: #N/A | AJN1: #N/A | AJO1: #N/A | AJP1: #N/A | AJQ1: #N/A | AJR1: #N/A | AJS1: #N/A | AJT1: #N/A | AJU1: #N/A | AJV1: #N/A | AJW1: #N/A | AJX1: #N/A | AJY1: #N/A | AJZ1: #N/A | AKA1: #N/A | AKB1: #N/A | AKC1: #N/A | AKD1: #N/A | AKE1: #N/A | AKF1: #N/A | AKG1: #N/A | AKH1: #N/A | AKI1: #N/A | AKJ1: #N/A | AKK1: #N/A | AKL1: #N/A | AKM1: #N/A | AKN1: #N/A | AKO1: #N/A | AKP1: #N/A | AKQ1: #N/A | AKR1: #N/A | AKS1: #N/A | AKT1: #N/A | AKU1: #N/A | AKV1: #N/A | AKW1: #N/A | AKX1: #N/A | AKY1: #N/A | AKZ1: #N/A | ALA1: #N/A | ALB1: #N/A | ALC1: #N/A | ALD1: #N/A | ALE1: #N/A | ALF1: #N/A | ALG1: #N/A | ALH1: #N/A | ALI1: #N/A | ALJ1: #N/A | ALK1: #N/A | ALL1: #N/A | ALM1: #N/A | ALN1: #N/A | ALO1: #N/A | ALP1: #N/A | ALQ1: #N/A | ALR1: #N/A | ALS1: #N/A | ALT1: #N/A | ALU1: #N/A | ALV1: #N/A | ALW1: #N/A | ALX1: #N/A | ALY1: #N/A | ALZ1: #N/A | AMA1: #N/A | AMB1: #N/A | AMC1: #N/A | AMD1: #N/A | AME1: #N/A | AMF1: #N/A | AMG1: #N/A | AMH1: #N/A
